Workbook

Sheet README
A1: LA DIPERIE — Dual-Location Inventory Optimization Workbook
A3: WHAT THIS WORKBOOK DOES
A4: Coordinates inventory across Oakville and High Park: calculates par levels,
A5: suggests transfers between stores, plans purchases, enforces cash caps in
A6: Low Cash Mode, tracks shared bulk purchases, and settles costs between locations.
A8: ⚠ SIMULATED DATA LOADED
A9: This workbook contains realistic simulated data for all 262 items. Unit costs,
A10: on-hand quantities, and weekly usage are estimates typical of a La Diperie-style
A11: ice cream dip shop. Replace the blue cells with your real numbers over time.
A13: HOW TO USE — 5 STEPS
A14: 1. Review ITEM_MASTER_CLEAN: Simulated costs & on-hand are pre-filled. Update to actuals.
A15: 2. Adjust SETTINGS: Lead time (3d), reorder cycle (7d), safety (3d), category speeds.
... A32: Green background = On-target / healthy

Sheet RAW_IMPORT
A1: Line | B1: Qty | C1: Description | D1: Brand | E1: Format | F1: Code
A2: 5 | C2: 9 CAKE WHITE LAYER 8" 24X354G | D2: RICH | E2: 24X354GM | F2: 62966
A3: 6 | C3: 9 CAKE CHOC LAYER 8" 24X354G | D3: RICH | E3: 24X354GM | F3: 62967
A4: 7 | C4: ICING PRE-WHIPPED VANILLA 6.8K | D4: RICH | E4: 6.8KG | F4: 62963
A5: 8 | C5: LADIP LABEL CHOCOLATE CAKE 1RLX50UN | D5: LA DIPERIE | E5: 1RLX50UN | F5: 22400
A6: 9 | C6: LADIP LABEL BIRTHDAY CAKE 1RLX50UN | D6: LA DIPERIE | E6: 1RLX50UN | F6: 22401
A7: 10 | C7: LADIP LABEL COOKIE & CREAM CAKE 1RL | D7: LA DIPERIE | E7: 1RLX50UN | F7: 22402
A8: 11 | C8: LADIP LABEL SALTD CARAMEL CAKE 1RL | D8: LA DIPERIE | E8: 1RLX50UN | F8: 22406
A9: 12 | C9: LADIP LABEL STRABERRY CAKE 1RLX50UN | D9: LA DIPERIE | E9: 1RLX50UN | F9: 22407
A10: 13 | C10: CAKE CARDBOARD 8" BLCK GOLD 100 | D10: CAPITALE | E10: 100UN | F10: 25800
A11: 14 | C11: ACETATE ROLL 3.5"X1250" 4MM 1RL | D11: CAPITALE | E11: 1RL | F11: 25802
A12: 18 | C12: CAKE CUPCAKE BLACKOUT 8X4UN | D12: COV CAKES | E12: 8X4UN | F12: 19689
A13: 19 | C13: CAKE CUPCAKE RED VELVET 8X4UN | D13: COV CAKES | E13: 8X4UN | F13: 19692
... A263: 626 | C263: LADIP BOX POPCORN 6X2.75X8.5 100 | D263: VIRAGE VER | E263: 100UN | F263: 61804
A266: COLUMN MAPPING
A267: Field | B267: Mapped To
A268: Item/SKU | B268: F (Code) → ITEM_MASTER_CLEAN col B
A269: Category | B269: Derived from section headers
A270: Supplier/Brand | B270: D (Brand)
A271: Unit Cost | B271: ITEM_MASTER_CLEAN col F (simulated)
A272: Case Pack | B272: ITEM_MASTER_CLEAN col G (parsed from Format)
A273: On-Hand Oakville | B273: ITEM_MASTER_CLEAN col H (simulated)
A274: On-Hand High Park | B274: ITEM_MASTER_CLEAN col I (simulated)
A275: Usage Oakville | B275: DEMAND_MODEL col E (simulated)
A276: Usage High Park | B276: DEMAND_MODEL col F (simulated)

Sheet SETTINGS
A1: OPERATIONAL SETTINGS
A2: Setting | B2: Value | C2: Unit
A3: Lead Time | B3: 3 | C3: days
A4: Reorder Cycle | B4: 7 | C4: days
A5: Safety Stock Days | B5: 3 | C5: days
A6: Low Cash Mode | B6: OFF | C6: ON/OFF
A7: Purchase Cash Cap | B7: 2000 | C7: $
A8: Transfer Min Threshold | B8: 5 | C8: units
A9: Slow Mover Max Par Cap | B9: 20 | C9: units
A12: CATEGORY SPEED STRATEGY
A13: Speed | B13: Coverage Target (days) | C13: Default Weekly Usage (units)
A14: Fast | B14: 21 | C14: 15
A15: Medium | B15: 14 | C15: 8
A16: Slow | B16: 10 | C16: 3
A18: CATEGORY-TO-SPEED MAPPING
A19: Category | B19: Speed
A20: BARRES DESSERT NON-LATIERE | B20: Slow
A21: BASE POUR SLUSH | B21: Medium
A22: BEIGNES/REMPLISSAGE/GARNITURES | B22: Medium
A23: BEVERAGES | B23: Fast
A24: BISCUITS & PATE A BISCUITS | B24: Fast
A25: BREUVAGES D'ETE -SUMMER DRINKS | B25: Medium
A26: CORNET / CONE | B26: Fast
A27: CREME GLACEE DUR & SORBETS 11.4L | B27: Fast
A28: DESSERTS | B28: Medium
A29: DIPS / TREMPETTES | B29: Fast
A30: DIVERSEY CLEANING | B30: Slow
... A41: TOPPINGS / GARNITURES | B41: Fast

Sheet ITEM_MASTER_CLEAN
A1: # | B1: Code | C1: Description | D1: Category | E1: Brand/Supplier | F1: Unit Cost ($) | G1: Case Pack | H1: On-Hand OAK | I1: On-Hand HP | J1: Flag: Missing Cost | K1: Flag: Missing Pack | L1: Flag: Missing Cat | M1: Flag: Duplicate
A2: 1 | B2: 62966 | C2: 9 CAKE WHITE LAYER 8" 24X354G | D2: GATEAUX & TARTES CREME GLACEE | E2: RICH | F2: 60.84 | G2: 24 | H2: 1 | I2: 5 | J2: =IF(F2=0,"MISSING","") | K2: =IF(G2<=0,"MISSING","") | L2: =IF(D2="","MISSING","") | M2: =IF(COUNTIF(B$2:B$263,B2)>1,"DUPLICATE","")
A3: 2 | B3: 62967 | C3: 9 CAKE CHOC LAYER 8" 24X354G | D3: GATEAUX & TARTES CREME GLACEE | E3: RICH | F3: 23.82 | G3: 24 | H3: 11 | I3: 0 | J3: =IF(F3=0,"MISSING","") | K3: =IF(G3<=0,"MISSING","") | L3: =IF(D3="","MISSING","") | M3: =IF(COUNTIF(B$2:B$263,B3)>1,"DUPLICATE","")
A4: 3 | B4: 62963 | C4: ICING PRE-WHIPPED VANILLA 6.8K | D4: GATEAUX & TARTES CREME GLACEE | E4: RICH | F4: 54.51 | G4: 1 | H4: 9 | I4: 6 | J4: =IF(F4=0,"MISSING","") | K4: =IF(G4<=0,"MISSING","") | L4: =IF(D4="","MISSING","") | M4: =IF(COUNTIF(B$2:B$263,B4)>1,"DUPLICATE","")
A5: 4 | B5: 22400 | C5: LADIP LABEL CHOCOLATE CAKE 1RLX50UN | D5: GATEAUX & TARTES CREME GLACEE | E5: LA DIPERIE | F5: 19.55 | G5: 1 | H5: 4 | I5: 1 | J5: =IF(F5=0,"MISSING","") | K5: =IF(G5<=0,"MISSING","") | L5: =IF(D5="","MISSING","") | M5: =IF(COUNTIF(B$2:B$263,B5)>1,"DUPLICATE","")
A6: 5 | B6: 22401 | C6: LADIP LABEL BIRTHDAY CAKE 1RLX50UN | D6: GATEAUX & TARTES CREME GLACEE | E6: LA DIPERIE | F6: 23.36 | G6: 1 | H6: 18 | I6: 4 | J6: =IF(F6=0,"MISSING","") | K6: =IF(G6<=0,"MISSING","") | L6: =IF(D6="","MISSING","") | M6: =IF(COUNTIF(B$2:B$263,B6)>1,"DUPLICATE","")
A7: 6 | B7: 22402 | C7: LADIP LABEL COOKIE & CREAM CAKE 1RL | D7: GATEAUX & TARTES CREME GLACEE | E7: LA DIPERIE | F7: 18.46 | G7: 1 | H7: 3 | I7: 3 | J7: =IF(F7=0,"MISSING","") | K7: =IF(G7<=0,"MISSING","") | L7: =IF(D7="","MISSING","") | M7: =IF(COUNTIF(B$2:B$263,B7)>1,"DUPLICATE","")
A8: 7 | B8: 22406 | C8: LADIP LABEL SALTD CARAMEL CAKE 1RL | D8: GATEAUX & TARTES CREME GLACEE | E8: LA DIPERIE | F8: 19.63 | G8: 1 | H8: 10 | I8: 0 | J8: =IF(F8=0,"MISSING","") | K8: =IF(G8<=0,"MISSING","") | L8: =IF(D8="","MISSING","") | M8: =IF(COUNTIF(B$2:B$263,B8)>1,"DUPLICATE","")
A9: 8 | B9: 22407 | C9: LADIP LABEL STRABERRY CAKE 1RLX50UN | D9: GATEAUX & TARTES CREME GLACEE | E9: LA DIPERIE | F9: 22.62 | G9: 1 | H9: 1 | I9: 11 | J9: =IF(F9=0,"MISSING","") | K9: =IF(G9<=0,"MISSING","") | L9: =IF(D9="","MISSING","") | M9: =IF(COUNTIF(B$2:B$263,B9)>1,"DUPLICATE","")
A10: 9 | B10: 25800 | C10: CAKE CARDBOARD 8" BLCK GOLD 100 | D10: GATEAUX & TARTES CREME GLACEE | E10: CAPITALE | F10: 15.99 | G10: 1 | H10: 11 | I10: 4 | J10: =IF(F10=0,"MISSING","") | K10: =IF(G10<=0,"MISSING","") | L10: =IF(D10="","MISSING","") | M10: =IF(COUNTIF(B$2:B$263,B10)>1,"DUPLICATE","")
A11: 10 | B11: 25802 | C11: ACETATE ROLL 3.5"X1250" 4MM 1RL | D11: GATEAUX & TARTES CREME GLACEE | E11: CAPITALE | F11: 23.42 | G11: 1 | H11: 14 | I11: 11 | J11: =IF(F11=0,"MISSING","") | K11: =IF(G11<=0,"MISSING","") | L11: =IF(D11="","MISSING","") | M11: =IF(COUNTIF(B$2:B$263,B11)>1,"DUPLICATE","")
A12: 11 | B12: 19689 | C12: CAKE CUPCAKE BLACKOUT 8X4UN | D12: GATEAUX FROMAGE & CUPCAKES | E12: COV CAKES | F12: 13.82 | G12: 8 | H12: 1 | I12: 1 | J12: =IF(F12=0,"MISSING","") | K12: =IF(G12<=0,"MISSING","") | L12: =IF(D12="","MISSING","") | M12: =IF(COUNTIF(B$2:B$263,B12)>1,"DUPLICATE","")
A13: 12 | B13: 19692 | C13: CAKE CUPCAKE RED VELVET 8X4UN | D13: GATEAUX FROMAGE & CUPCAKES | E13: COV CAKES | F13: 21.36 | G13: 8 | H13: 6 | I13: 4 | J13: =IF(F13=0,"MISSING","") | K13: =IF(G13<=0,"MISSING","") | L13: =IF(D13="","MISSING","") | M13: =IF(COUNTIF(B$2:B$263,B13)>1,"DUPLICATE","")
... A263: 262 | B263: 61804 | C263: LADIP BOX POPCORN 6X2.75X8.5 100 | D263: POPCORN & PACKAGING | E263: VIRAGE VER | F263: 16.46 | G263: 1 | H263: 1 | I263: 1 | J263: =IF(F263=0,"MISSING","") | K263: =IF(G263<=0,"MISSING","") | L263: =IF(D263="","MISSING","") | M263: =IF(COUNTIF(B$2:B$263,B263)>1,"DUPLICATE","")

Sheet DEMAND_MODEL
A1: # | B1: Code | C1: Description | D1: Category | E1: Weekly Usage OAK (override) | F1: Weekly Usage HP (override) | G1: Category Speed | H1: Category Default Wkly | I1: Effective Wkly OAK | J1: Effective Wkly HP | K1: Avg Daily OAK | L1: Avg Daily HP
A2: =ITEM_MASTER_CLEAN!A2 -> 1 | B2: =ITEM_MASTER_CLEAN!B2 -> 62966 | C2: =ITEM_MASTER_CLEAN!C2 -> 9 CAKE WHITE LAYER 8" 24X354G | D2: =ITEM_MASTER_CLEAN!D2 -> GATEAUX & TARTES CREME GLACEE | E2: 1 | F2: 3 | G2: =IFERROR(VLOOKUP(D2,SETTINGS!A20:B41,2,FALSE()),"Medium") -> Medium | H2: =IFERROR(VLOOKUP(G2,SETTINGS!A14:C16,3,FALSE()),5) -> 8 | I2: =IF(E2>0,E2,H2) -> 1 | J2: =IF(F2>0,F2,H2) -> 3 | K2: =I2/7 -> 0.14285714 | L2: =J2/7 -> 0.42857143
A3: =ITEM_MASTER_CLEAN!A3 -> 2 | B3: =ITEM_MASTER_CLEAN!B3 -> 62967 | C3: =ITEM_MASTER_CLEAN!C3 -> 9 CAKE CHOC LAYER 8" 24X354G | D3: =ITEM_MASTER_CLEAN!D3 -> GATEAUX & TARTES CREME GLACEE | E3: 4 | F3: 1 | G3: =IFERROR(VLOOKUP(D3,SETTINGS!A20:B41,2,FALSE()),"Medium") -> Medium | H3: =IFERROR(VLOOKUP(G3,SETTINGS!A14:C16,3,FALSE()),5) -> 8 | I3: =IF(E3>0,E3,H3) -> 4 | J3: =IF(F3>0,F3,H3) -> 1 | K3: =I3/7 -> 0.57142857 | L3: =J3/7 -> 0.14285714
A4: =ITEM_MASTER_CLEAN!A4 -> 3 | B4: =ITEM_MASTER_CLEAN!B4 -> 62963 | C4: =ITEM_MASTER_CLEAN!C4 -> ICING PRE-WHIPPED VANILLA 6.8K | D4: =ITEM_MASTER_CLEAN!D4 -> GATEAUX & TARTES CREME GLACEE | E4: 2 | F4: 2 | G4: =IFERROR(VLOOKUP(D4,SETTINGS!A20:B41,2,FALSE()),"Medium") -> Medium | H4: =IFERROR(VLOOKUP(G4,SETTINGS!A14:C16,3,FALSE()),5) -> 8 | I4: =IF(E4>0,E4,H4) -> 2 | J4: =IF(F4>0,F4,H4) -> 2 | K4: =I4/7 -> 0.28571429 | L4: =J4/7 -> 0.28571429
A5: =ITEM_MASTER_CLEAN!A5 -> 4 | B5: =ITEM_MASTER_CLEAN!B5 -> 22400 | C5: =ITEM_MASTER_CLEAN!C5 -> LADIP LABEL CHOCOLATE CAKE 1RLX50UN | D5: =ITEM_MASTER_CLEAN!D5 -> GATEAUX & TARTES CREME GLACEE | E5: 3 | F5: 1 | G5: =IFERROR(VLOOKUP(D5,SETTINGS!A20:B41,2,FALSE()),"Medium") -> Medium | H5: =IFERROR(VLOOKUP(G5,SETTINGS!A14:C16,3,FALSE()),5) -> 8 | I5: =IF(E5>0,E5,H5) -> 3 | J5: =IF(F5>0,F5,H5) -> 1 | K5: =I5/7 -> 0.42857143 | L5: =J5/7 -> 0.14285714
A6: =ITEM_MASTER_CLEAN!A6 -> 5 | B6: =ITEM_MASTER_CLEAN!B6 -> 22401 | C6: =ITEM_MASTER_CLEAN!C6 -> LADIP LABEL BIRTHDAY CAKE 1RLX50UN | D6: =ITEM_MASTER_CLEAN!D6 -> GATEAUX & TARTES CREME GLACEE | E6: 4 | F6: 1 | G6: =IFERROR(VLOOKUP(D6,SETTINGS!A20:B41,2,FALSE()),"Medium") -> Medium | H6: =IFERROR(VLOOKUP(G6,SETTINGS!A14:C16,3,FALSE()),5) -> 8 | I6: =IF(E6>0,E6,H6) -> 4 | J6: =IF(F6>0,F6,H6) -> 1 | K6: =I6/7 -> 0.57142857 | L6: =J6/7 -> 0.14285714
A7: =ITEM_MASTER_CLEAN!A7 -> 6 | B7: =ITEM_MASTER_CLEAN!B7 -> 22402 | C7: =ITEM_MASTER_CLEAN!C7 -> LADIP LABEL COOKIE & CREAM CAKE 1RL | D7: =ITEM_MASTER_CLEAN!D7 -> GATEAUX & TARTES CREME GLACEE | E7: 2 | F7: 2 | G7: =IFERROR(VLOOKUP(D7,SETTINGS!A20:B41,2,FALSE()),"Medium") -> Medium | H7: =IFERROR(VLOOKUP(G7,SETTINGS!A14:C16,3,FALSE()),5) -> 8 | I7: =IF(E7>0,E7,H7) -> 2 | J7: =IF(F7>0,F7,H7) -> 2 | K7: =I7/7 -> 0.28571429 | L7: =J7/7 -> 0.28571429
A8: =ITEM_MASTER_CLEAN!A8 -> 7 | B8: =ITEM_MASTER_CLEAN!B8 -> 22406 | C8: =ITEM_MASTER_CLEAN!C8 -> LADIP LABEL SALTD CARAMEL CAKE 1RL | D8: =ITEM_MASTER_CLEAN!D8 -> GATEAUX & TARTES CREME GLACEE | E8: 3 | F8: 1 | G8: =IFERROR(VLOOKUP(D8,SETTINGS!A20:B41,2,FALSE()),"Medium") -> Medium | H8: =IFERROR(VLOOKUP(G8,SETTINGS!A14:C16,3,FALSE()),5) -> 8 | I8: =IF(E8>0,E8,H8) -> 3 | J8: =IF(F8>0,F8,H8) -> 1 | K8: =I8/7 -> 0.42857143 | L8: =J8/7 -> 0.14285714
A9: =ITEM_MASTER_CLEAN!A9 -> 8 | B9: =ITEM_MASTER_CLEAN!B9 -> 22407 | C9: =ITEM_MASTER_CLEAN!C9 -> LADIP LABEL STRABERRY CAKE 1RLX50UN | D9: =ITEM_MASTER_CLEAN!D9 -> GATEAUX & TARTES CREME GLACEE | E9: 3 | F9: 3 | G9: =IFERROR(VLOOKUP(D9,SETTINGS!A20:B41,2,FALSE()),"Medium") -> Medium | H9: =IFERROR(VLOOKUP(G9,SETTINGS!A14:C16,3,FALSE()),5) -> 8 | I9: =IF(E9>0,E9,H9) -> 3 | J9: =IF(F9>0,F9,H9) -> 3 | K9: =I9/7 -> 0.42857143 | L9: =J9/7 -> 0.42857143
A10: =ITEM_MASTER_CLEAN!A10 -> 9 | B10: =ITEM_MASTER_CLEAN!B10 -> 25800 | C10: =ITEM_MASTER_CLEAN!C10 -> CAKE CARDBOARD 8" BLCK GOLD 100 | D10: =ITEM_MASTER_CLEAN!D10 -> GATEAUX & TARTES CREME GLACEE | E10: 3 | F10: 1 | G10: =IFERROR(VLOOKUP(D10,SETTINGS!A20:B41,2,FALSE()),"Medium") -> Medium | H10: =IFERROR(VLOOKUP(G10,SETTINGS!A14:C16,3,FALSE()),5) -> 8 | I10: =IF(E10>0,E10,H10) -> 3 | J10: =IF(F10>0,F10,H10) -> 1 | K10: =I10/7 -> 0.42857143 | L10: =J10/7 -> 0.14285714
A11: =ITEM_MASTER_CLEAN!A11 -> 10 | B11: =ITEM_MASTER_CLEAN!B11 -> 25802 | C11: =ITEM_MASTER_CLEAN!C11 -> ACETATE ROLL 3.5"X1250" 4MM 1RL | D11: =ITEM_MASTER_CLEAN!D11 -> GATEAUX & TARTES CREME GLACEE | E11: 3 | F11: 3 | G11: =IFERROR(VLOOKUP(D11,SETTINGS!A20:B41,2,FALSE()),"Medium") -> Medium | H11: =IFERROR(VLOOKUP(G11,SETTINGS!A14:C16,3,FALSE()),5) -> 8 | I11: =IF(E11>0,E11,H11) -> 3 | J11: =IF(F11>0,F11,H11) -> 3 | K11: =I11/7 -> 0.42857143 | L11: =J11/7 -> 0.42857143
A12: =ITEM_MASTER_CLEAN!A12 -> 11 | B12: =ITEM_MASTER_CLEAN!B12 -> 19689 | C12: =ITEM_MASTER_CLEAN!C12 -> CAKE CUPCAKE BLACKOUT 8X4UN | D12: =ITEM_MASTER_CLEAN!D12 -> GATEAUX FROMAGE & CUPCAKES | E12: 1 | F12: 1 | G12: =IFERROR(VLOOKUP(D12,SETTINGS!A20:B41,2,FALSE()),"Medium") -> Medium | H12: =IFERROR(VLOOKUP(G12,SETTINGS!A14:C16,3,FALSE()),5) -> 8 | I12: =IF(E12>0,E12,H12) -> 1 | J12: =IF(F12>0,F12,H12) -> 1 | K12: =I12/7 -> 0.14285714 | L12: =J12/7 -> 0.14285714
A13: =ITEM_MASTER_CLEAN!A13 -> 12 | B13: =ITEM_MASTER_CLEAN!B13 -> 19692 | C13: =ITEM_MASTER_CLEAN!C13 -> CAKE CUPCAKE RED VELVET 8X4UN | D13: =ITEM_MASTER_CLEAN!D13 -> GATEAUX FROMAGE & CUPCAKES | E13: 2 | F13: 1 | G13: =IFERROR(VLOOKUP(D13,SETTINGS!A20:B41,2,FALSE()),"Medium") -> Medium | H13: =IFERROR(VLOOKUP(G13,SETTINGS!A14:C16,3,FALSE()),5) -> 8 | I13: =IF(E13>0,E13,H13) -> 2 | J13: =IF(F13>0,F13,H13) -> 1 | K13: =I13/7 -> 0.28571429 | L13: =J13/7 -> 0.14285714
A14: =ITEM_MASTER_CLEAN!A14 -> 13 | B14: =ITEM_MASTER_CLEAN!B14 -> 19693 | C14: =ITEM_MASTER_CLEAN!C14 -> CAKE CUPCAKE VANILLA BEAN 8X4UN | D14: =ITEM_MASTER_CLEAN!D14 -> GATEAUX FROMAGE & CUPCAKES | E14: 1 | F14: 2 | G14: =IFERROR(VLOOKUP(D14,SETTINGS!A20:B41,2,FALSE()),"Medium") -> Medium | H14: =IFERROR(VLOOKUP(G14,SETTINGS!A14:C16,3,FALSE()),5) -> 8 | I14: =IF(E14>0,E14,H14) -> 1 | J14: =IF(F14>0,F14,H14) -> 2 | K14: =I14/7 -> 0.14285714 | L14: =J14/7 -> 0.28571429
A15: =ITEM_MASTER_CLEAN!A15 -> 14 | B15: =ITEM_MASTER_CLEAN!B15 -> 19688 | C15: =ITEM_MASTER_CLEAN!C15 -> CAKE CHEESE ORIGINAL 6X6" | D15: =ITEM_MASTER_CLEAN!D15 -> GATEAUX FROMAGE & CUPCAKES | E15: 1 | F15: 2 | G15: =IFERROR(VLOOKUP(D15,SETTINGS!A20:B41,2,FALSE()),"Medium") -> Medium | H15: =IFERROR(VLOOKUP(G15,SETTINGS!A14:C16,3,FALSE()),5) -> 8 | I15: =IF(E15>0,E15,H15) -> 1 | J15: =IF(F15>0,F15,H15) -> 2 | K15: =I15/7 -> 0.14285714 | L15: =J15/7 -> 0.28571429
A16: =ITEM_MASTER_CLEAN!A16 -> 15 | B16: =ITEM_MASTER_CLEAN!B16 -> 19687 | C16: =ITEM_MASTER_CLEAN!C16 -> CAKE CHEESE WHT CHOC/RASP 6X6" | D16: =ITEM_MASTER_CLEAN!D16 -> GATEAUX FROMAGE & CUPCAKES | E16: 3 | F16: 2 | G16: =IFERROR(VLOOKUP(D16,SETTINGS!A20:B41,2,FALSE()),"Medium") -> Medium | H16: =IFERROR(VLOOKUP(G16,SETTINGS!A14:C16,3,FALSE()),5) -> 8 | I16: =IF(E16>0,E16,H16) -> 3 | J16: =IF(F16>0,F16,H16) -> 2 | K16: =I16/7 -> 0.42857143 | L16: =J16/7 -> 0.28571429
A17: =ITEM_MASTER_CLEAN!A17 -> 16 | B17: =ITEM_MASTER_CLEAN!B17 -> 19685 | C17: =ITEM_MASTER_CLEAN!C17 -> CAKE CHEESE CHOC MOUSSE 6X6" | D17: =ITEM_MASTER_CLEAN!D17 -> GATEAUX FROMAGE & CUPCAKES | E17: 1 | F17: 1 | G17: =IFERROR(VLOOKUP(D17,SETTINGS!A20:B41,2,FALSE()),"Medium") -> Medium | H17: =IFERROR(VLOOKUP(G17,SETTINGS!A14:C16,3,FALSE()),5) -> 8 | I17: =IF(E17>0,E17,H17) -> 1 | J17: =IF(F17>0,F17,H17) -> 1 | K17: =I17/7 -> 0.14285714 | L17: =J17/7 -> 0.14285714
A18: =ITEM_MASTER_CLEAN!A18 -> 17 | B18: =ITEM_MASTER_CLEAN!B18 -> 19628 | C18: =ITEM_MASTER_CLEAN!C18 -> CAKE CHEESE CAKE FACTORY 2X14UN | D18: =ITEM_MASTER_CLEAN!D18 -> GATEAUX FROMAGE & CUPCAKES | E18: 2 | F18: 1 | G18: =IFERROR(VLOOKUP(D18,SETTINGS!A20:B41,2,FALSE()),"Medium") -> Medium | H18: =IFERROR(VLOOKUP(G18,SETTINGS!A14:C16,3,FALSE()),5) -> 8 | I18: =IF(E18>0,E18,H18) -> 2 | J18: =IF(F18>0,F18,H18) -> 1 | K18: =I18/7 -> 0.28571429 | L18: =J18/7 -> 0.14285714
A19: =ITEM_MASTER_CLEAN!A19 -> 18 | B19: =ITEM_MASTER_CLEAN!B19 -> 16992 | C19: =ITEM_MASTER_CLEAN!C19 -> CAKE CHEESE MANGO LIME X2 | D19: =ITEM_MASTER_CLEAN!D19 -> GATEAUX FROMAGE & CUPCAKES | E19: 1 | F19: 2 | G19: =IFERROR(VLOOKUP(D19,SETTINGS!A20:B41,2,FALSE()),"Medium") -> Medium | H19: =IFERROR(VLOOKUP(G19,SETTINGS!A14:C16,3,FALSE()),5) -> 8 | I19: =IF(E19>0,E19,H19) -> 1 | J19: =IF(F19>0,F19,H19) -> 2 | K19: =I19/7 -> 0.14285714 | L19: =J19/7 -> 0.28571429
A20: =ITEM_MASTER_CLEAN!A20 -> 19 | B20: =ITEM_MASTER_CLEAN!B20 -> 16995 | C20: =ITEM_MASTER_CLEAN!C20 -> CAKE CHEESE CINNABON X2 | D20: =ITEM_MASTER_CLEAN!D20 -> GATEAUX FROMAGE & CUPCAKES | E20: 1 | F20: 2 | G20: =IFERROR(VLOOKUP(D20,SETTINGS!A20:B41,2,FALSE()),"Medium") -> Medium | H20: =IFERROR(VLOOKUP(G20,SETTINGS!A14:C16,3,FALSE()),5) -> 8 | I20: =IF(E20>0,E20,H20) -> 1 | J20: =IF(F20>0,F20,H20) -> 2 | K20: =I20/7 -> 0.14285714 | L20: =J20/7 -> 0.28571429
A21: =ITEM_MASTER_CLEAN!A21 -> 20 | B21: =ITEM_MASTER_CLEAN!B21 -> 19629 | C21: =ITEM_MASTER_CLEAN!C21 -> CAKE GODIVA DBL CHOC CHEESE 2X28PC | D21: =ITEM_MASTER_CLEAN!D21 -> GATEAUX FROMAGE & CUPCAKES | E21: 1 | F21: 2 | G21: =IFERROR(VLOOKUP(D21,SETTINGS!A20:B41,2,FALSE()),"Medium") -> Medium | H21: =IFERROR(VLOOKUP(G21,SETTINGS!A14:C16,3,FALSE()),5) -> 8 | I21: =IF(E21>0,E21,H21) -> 1 | J21: =IF(F21>0,F21,H21) -> 2 | K21: =I21/7 -> 0.14285714 | L21: =J21/7 -> 0.28571429
A22: =ITEM_MASTER_CLEAN!A22 -> 21 | B22: =ITEM_MASTER_CLEAN!B22 -> 16993 | C22: =ITEM_MASTER_CLEAN!C22 -> CAKE CHEESE OREO X2 | D22: =ITEM_MASTER_CLEAN!D22 -> GATEAUX FROMAGE & CUPCAKES | E22: 2 | F22: 2 | G22: =IFERROR(VLOOKUP(D22,SETTINGS!A20:B41,2,FALSE()),"Medium") -> Medium | H22: =IFERROR(VLOOKUP(G22,SETTINGS!A14:C16,3,FALSE()),5) -> 8 | I22: =IF(E22>0,E22,H22) -> 2 | J22: =IF(F22>0,F22,H22) -> 2 | K22: =I22/7 -> 0.28571429 | L22: =J22/7 -> 0.28571429
A23: =ITEM_MASTER_CLEAN!A23 -> 22 | B23: =ITEM_MASTER_CLEAN!B23 -> 16988 | C23: =ITEM_MASTER_CLEAN!C23 -> CAKE CHEESE BANANA FOSTER X2 | D23: =ITEM_MASTER_CLEAN!D23 -> GATEAUX FROMAGE & CUPCAKES | E23: 3 | F23: 1 | G23: =IFERROR(VLOOKUP(D23,SETTINGS!A20:B41,2,FALSE()),"Medium") -> Medium | H23: =IFERROR(VLOOKUP(G23,SETTINGS!A14:C16,3,FALSE()),5) -> 8 | I23: =IF(E23>0,E23,H23) -> 3 | J23: =IF(F23>0,F23,H23) -> 1 | K23: =I23/7 -> 0.42857143 | L23: =J23/7 -> 0.14285714
A24: =ITEM_MASTER_CLEAN!A24 -> 23 | B24: =ITEM_MASTER_CLEAN!B24 -> 16987 | C24: =ITEM_MASTER_CLEAN!C24 -> CAKE CHEESE WILD STRWBERRY X2 | D24: =ITEM_MASTER_CLEAN!D24 -> GATEAUX FROMAGE & CUPCAKES | E24: 1 | F24: 2 | G24: =IFERROR(VLOOKUP(D24,SETTINGS!A20:B41,2,FALSE()),"Medium") -> Medium | H24: =IFERROR(VLOOKUP(G24,SETTINGS!A14:C16,3,FALSE()),5) -> 8 | I24: =IF(E24>0,E24,H24) -> 1 | J24: =IF(F24>0,F24,H24) -> 2 | K24: =I24/7 -> 0.14285714 | L24: =J24/7 -> 0.28571429
A25: =ITEM_MASTER_CLEAN!A25 -> 24 | B25: =ITEM_MASTER_CLEAN!B25 -> 16994 | C25: =ITEM_MASTER_CLEAN!C25 -> CAKE CHEESE DULCE DE LECHE X2 | D25: =ITEM_MASTER_CLEAN!D25 -> GATEAUX FROMAGE & CUPCAKES | E25: 3 | F25: 1 | G25: =IFERROR(VLOOKUP(D25,SETTINGS!A20:B41,2,FALSE()),"Medium") -> Medium | H25: =IFERROR(VLOOKUP(G25,SETTINGS!A14:C16,3,FALSE()),5) -> 8 | I25: =IF(E25>0,E25,H25) -> 3 | J25: =IF(F25>0,F25,H25) -> 1 | K25: =I25/7 -> 0.42857143 | L25: =J25/7 -> 0.14285714
A26: =ITEM_MASTER_CLEAN!A26 -> 25 | B26: =ITEM_MASTER_CLEAN!B26 -> 19694 | C26: =ITEM_MASTER_CLEAN!C26 -> CAKE REESE P.BUTTER CHOC 2X28PC | D26: =ITEM_MASTER_CLEAN!D26 -> GATEAUX FROMAGE & CUPCAKES | E26: 1 | F26: 1 | G26: =IFERROR(VLOOKUP(D26,SETTINGS!A20:B41,2,FALSE()),"Medium") -> Medium | H26: =IFERROR(VLOOKUP(G26,SETTINGS!A14:C16,3,FALSE()),5) -> 8 | I26: =IF(E26>0,E26,H26) -> 1 | J26: =IF(F26>0,F26,H26) -> 1 | K26: =I26/7 -> 0.14285714 | L26: =J26/7 -> 0.14285714
A27: =ITEM_MASTER_CLEAN!A27 -> 26 | B27: =ITEM_MASTER_CLEAN!B27 -> 16991 | C27: =ITEM_MASTER_CLEAN!C27 -> CAKE CHEESE RED VELVET X2 | D27: =ITEM_MASTER_CLEAN!D27 -> GATEAUX FROMAGE & CUPCAKES | E27: 3 | F27: 2 | G27: =IFERROR(VLOOKUP(D27,SETTINGS!A20:B41,2,FALSE()),"Medium") -> Medium | H27: =IFERROR(VLOOKUP(G27,SETTINGS!A14:C16,3,FALSE()),5) -> 8 | I27: =IF(E27>0,E27,H27) -> 3 | J27: =IF(F27>0,F27,H27) -> 2 | K27: =I27/7 -> 0.42857143 | L27: =J27/7 -> 0.28571429
A28: =ITEM_MASTER_CLEAN!A28 -> 27 | B28: =ITEM_MASTER_CLEAN!B28 -> 16989 | C28: =ITEM_MASTER_CLEAN!C28 -> CAKE CHEESE TUXEDO MOUSSE X2 | D28: =ITEM_MASTER_CLEAN!D28 -> GATEAUX FROMAGE & CUPCAKES | E28: 1 | F28: 1 | G28: =IFERROR(VLOOKUP(D28,SETTINGS!A20:B41,2,FALSE()),"Medium") -> Medium | H28: =IFERROR(VLOOKUP(G28,SETTINGS!A14:C16,3,FALSE()),5) -> 8 | I28: =IF(E28>0,E28,H28) -> 1 | J28: =IF(F28>0,F28,H28) -> 1 | K28: =I28/7 -> 0.14285714 | L28: =J28/7 -> 0.14285714
A29: =ITEM_MASTER_CLEAN!A29 -> 28 | B29: =ITEM_MASTER_CLEAN!B29 -> 19630 | C29: =ITEM_MASTER_CLEAN!C29 -> CAKE WHITE CHOC RSPBRY CHEESE X2 | D29: =ITEM_MASTER_CLEAN!D29 -> GATEAUX FROMAGE & CUPCAKES | E29: 3 | F29: 1 | G29: =IFERROR(VLOOKUP(D29,SETTINGS!A20:B41,2,FALSE()),"Medium") -> Medium | H29: =IFERROR(VLOOKUP(G29,SETTINGS!A14:C16,3,FALSE()),5) -> 8 | I29: =IF(E29>0,E29,H29) -> 3 | J29: =IF(F29>0,F29,H29) -> 1 | K29: =I29/7 -> 0.42857143 | L29: =J29/7 -> 0.14285714
A30: =ITEM_MASTER_CLEAN!A30 -> 29 | B30: =ITEM_MASTER_CLEAN!B30 -> 44985 | C30: =ITEM_MASTER_CLEAN!C30 -> BISC DOUGH OREO V-VIT0013V 5K | D30: =ITEM_MASTER_CLEAN!D30 -> BISCUITS & PATE A BISCUITS | E30: 6 | F30: 1 | G30: =IFERROR(VLOOKUP(D30,SETTINGS!A20:B41,2,FALSE()),"Medium") -> Fast | H30: =IFERROR(VLOOKUP(G30,SETTINGS!A14:C16,3,FALSE()),5) -> 15 | I30: =IF(E30>0,E30,H30) -> 6 | J30: =IF(F30>0,F30,H30) -> 1 | K30: =I30/7 -> 0.85714286 | L30: =J30/7 -> 0.14285714
A31: =ITEM_MASTER_CLEAN!A31 -> 30 | B31: =ITEM_MASTER_CLEAN!B31 -> 44961 | C31: =ITEM_MASTER_CLEAN!C31 -> BISC DOUGH BLK CHOCO MED SWEET 5K | D31: =ITEM_MASTER_CLEAN!D31 -> BISCUITS & PATE A BISCUITS | E31: 3 | F31: 3 | G31: =IFERROR(VLOOKUP(D31,SETTINGS!A20:B41,2,FALSE()),"Medium") -> Fast | H31: =IFERROR(VLOOKUP(G31,SETTINGS!A14:C16,3,FALSE()),5) -> 15 | I31: =IF(E31>0,E31,H31) -> 3 | J31: =IF(F31>0,F31,H31) -> 3 | K31: =I31/7 -> 0.42857143 | L31: =J31/7 -> 0.42857143
A32: =ITEM_MASTER_CLEAN!A32 -> 31 | B32: =ITEM_MASTER_CLEAN!B32 -> 44962 | C32: =ITEM_MASTER_CLEAN!C32 -> BISC DOUGH DBL CHOCO PAIL 5K | D32: =ITEM_MASTER_CLEAN!D32 -> BISCUITS & PATE A BISCUITS | E32: 6 | F32: 1 | G32: =IFERROR(VLOOKUP(D32,SETTINGS!A20:B41,2,FALSE()),"Medium") -> Fast | H32: =IFERROR(VLOOKUP(G32,SETTINGS!A14:C16,3,FALSE()),5) -> 15 | I32: =IF(E32>0,E32,H32) -> 6 | J32: =IF(F32>0,F32,H32) -> 1 | K32: =I32/7 -> 0.85714286 | L32: =J32/7 -> 0.14285714
A33: =ITEM_MASTER_CLEAN!A33 -> 32 | B33: =ITEM_MASTER_CLEAN!B33 -> 63927 | C33: =ITEM_MASTER_CLEAN!C33 -> Bisc PUCK Dbl Choc 160x2oz | D33: =ITEM_MASTER_CLEAN!D33 -> BISCUITS & PATE A BISCUITS | E33: 4 | F33: 3 | G33: =IFERROR(VLOOKUP(D33,SETTINGS!A20:B41,2,FALSE()),"Medium") -> Fast | H33: =IFERROR(VLOOKUP(G33,SETTINGS!A14:C16,3,FALSE()),5) -> 15 | I33: =IF(E33>0,E33,H33) -> 4 | J33: =IF(F33>0,F33,H33) -> 3 | K33: =I33/7 -> 0.57142857 | L33: =J33/7 -> 0.42857143
A34: =ITEM_MASTER_CLEAN!A34 -> 33 | B34: =ITEM_MASTER_CLEAN!B34 -> 64106 | C34: =ITEM_MASTER_CLEAN!C34 -> Bisc PUCK ChocBln/Maca 160x2oz | D34: =ITEM_MASTER_CLEAN!D34 -> BISCUITS & PATE A BISCUITS | E34: 2 | F34: 3 | G34: =IFERROR(VLOOKUP(D34,SETTINGS!A20:B41,2,FALSE()),"Medium") -> Fast | H34: =IFERROR(VLOOKUP(G34,SETTINGS!A14:C16,3,FALSE()),5) -> 15 | I34: =IF(E34>0,E34,H34) -> 2 | J34: =IF(F34>0,F34,H34) -> 3 | K34: =I34/7 -> 0.28571429 | L34: =J34/7 -> 0.42857143
A35: =ITEM_MASTER_CLEAN!A35 -> 34 | B35: =ITEM_MASTER_CLEAN!B35 -> 63934 | C35: =ITEM_MASTER_CLEAN!C35 -> Bisc PUCK ChocChunk 160x2oz | D35: =ITEM_MASTER_CLEAN!D35 -> BISCUITS & PATE A BISCUITS | E35: 3 | F35: 3 | G35: =IFERROR(VLOOKUP(D35,SETTINGS!A20:B41,2,FALSE()),"Medium") -> Fast | H35: =IFERROR(VLOOKUP(G35,SETTINGS!A14:C16,3,FALSE()),5) -> 15 | I35: =IF(E35>0,E35,H35) -> 3 | J35: =IF(F35>0,F35,H35) -> 3 | K35: =I35/7 -> 0.42857143 | L35: =J35/7 -> 0.42857143
A36: =ITEM_MASTER_CLEAN!A36 -> 35 | B36: =ITEM_MASTER_CLEAN!B36 -> 12596 | C36: =ITEM_MASTER_CLEAN!C36 -> MTY TREAT FOR DOGS 24UN | D36: =ITEM_MASTER_CLEAN!D36 -> BISCUITS & PATE A BISCUITS | E36: 4 | F36: 1 | G36: =IFERROR(VLOOKUP(D36,SETTINGS!A20:B41,2,FALSE()),"Medium") -> Fast | H36: =IFERROR(VLOOKUP(G36,SETTINGS!A14:C16,3,FALSE()),5) -> 15 | I36: =IF(E36>0,E36,H36) -> 4 | J36: =IF(F36>0,F36,H36) -> 1 | K36: =I36/7 -> 0.57142857 | L36: =J36/7 -> 0.14285714
A37: =ITEM_MASTER_CLEAN!A37 -> 36 | B37: =ITEM_MASTER_CLEAN!B37 -> 48219 | C37: =ITEM_MASTER_CLEAN!C37 -> BISC LOTUS BISCOFF 10X250G | D37: =ITEM_MASTER_CLEAN!D37 -> BISCUITS & PATE A BISCUITS | E37: 5 | F37: 4 | G37: =IFERROR(VLOOKUP(D37,SETTINGS!A20:B41,2,FALSE()),"Medium") -> Fast | H37: =IFERROR(VLOOKUP(G37,SETTINGS!A14:C16,3,FALSE()),5) -> 15 | I37: =IF(E37>0,E37,H37) -> 5 | J37: =IF(F37>0,F37,H37) -> 4 | K37: =I37/7 -> 0.71428571 | L37: =J37/7 -> 0.57142857
A38: =ITEM_MASTER_CLEAN!A38 -> 37 | B38: =ITEM_MASTER_CLEAN!B38 -> 39811 | C38: =ITEM_MASTER_CLEAN!C38 -> DONUT REGULAR 00726 140X28G | D38: =ITEM_MASTER_CLEAN!D38 -> BEIGNES/REMPLISSAGE/GARNITURES | E38: 4 | F38: 1 | G38: =IFERROR(VLOOKUP(D38,SETTINGS!A20:B41,2,FALSE()),"Medium") -> Medium | H38: =IFERROR(VLOOKUP(G38,SETTINGS!A14:C16,3,FALSE()),5) -> 8 | I38: =IF(E38>0,E38,H38) -> 4 | J38: =IF(F38>0,F38,H38) -> 1 | K38: =I38/7 -> 0.57142857 | L38: =J38/7 -> 0.14285714
A39: =ITEM_MASTER_CLEAN!A39 -> 38 | B39: =ITEM_MASTER_CLEAN!B39 -> 43328 | C39: =ITEM_MASTER_CLEAN!C39 -> DONUT MINI VANILLA 2442 300X12G | D39: =ITEM_MASTER_CLEAN!D39 -> BEIGNES/REMPLISSAGE/GARNITURES | E39: 3 | F39: 3 | G39: =IFERROR(VLOOKUP(D39,SETTINGS!A20:B41,2,FALSE()),"Medium") -> Medium | H39: =IFERROR(VLOOKUP(G39,SETTINGS!A14:C16,3,FALSE()),5) -> 8 | I39: =IF(E39>0,E39,H39) -> 3 | J39: =IF(F39>0,F39,H39) -> 3 | K39: =I39/7 -> 0.42857143 | L39: =J39/7 -> 0.42857143
A40: =ITEM_MASTER_CLEAN!A40 -> 39 | B40: =ITEM_MASTER_CLEAN!B40 -> 50170 | C40: =ITEM_MASTER_CLEAN!C40 -> MTY CHOC FF 3100051 5X1L | D40: =ITEM_MASTER_CLEAN!D40 -> BEIGNES/REMPLISSAGE/GARNITURES | E40: 2 | F40: 2 | G40: =IFERROR(VLOOKUP(D40,SETTINGS!A20:B41,2,FALSE()),"Medium") -> Medium | H40: =IFERROR(VLOOKUP(G40,SETTINGS!A14:C16,3,FALSE()),5) -> 8 | I40: =IF(E40>0,E40,H40) -> 2 | J40: =IF(F40>0,F40,H40) -> 2 | K40: =I40/7 -> 0.28571429 | L40: =J40/7 -> 0.28571429
...

Sheet PAR_LEVELS
A1: # | B1: Code | C1: Description | D1: Category Speed | E1: Avg Daily OAK | F1: Avg Daily HP | G1: Coverage Days | H1: Par OAK (raw) | I1: Par HP (raw) | J1: Par OAK (capped) | K1: Par HP (capped)
A2: =DEMAND_MODEL!A2 -> 1 | B2: =DEMAND_MODEL!B2 -> 62966 | C2: =DEMAND_MODEL!C2 -> 9 CAKE WHITE LAYER 8" 24X354G | D2: =DEMAND_MODEL!G2 -> Medium | E2: =DEMAND_MODEL!K2 -> 0.14285714 | F2: =DEMAND_MODEL!L2 -> 0.42857143 | G2: =IFERROR(VLOOKUP(D2,SETTINGS!A14:B16,2,FALSE()),14) -> 14 | H2: =E2*(LeadTime+ReorderCycle+SafetyDays) -> 1.8571429 | I2: =F2*(LeadTime+ReorderCycle+SafetyDays) -> 5.5714286 | J2: =IF(D2="Slow",MIN(H2,SlowMoverCap),H2) -> 1.8571429 | K2: =IF(D2="Slow",MIN(I2,SlowMoverCap),I2) -> 5.5714286
A3: =DEMAND_MODEL!A3 -> 2 | B3: =DEMAND_MODEL!B3 -> 62967 | C3: =DEMAND_MODEL!C3 -> 9 CAKE CHOC LAYER 8" 24X354G | D3: =DEMAND_MODEL!G3 -> Medium | E3: =DEMAND_MODEL!K3 -> 0.57142857 | F3: =DEMAND_MODEL!L3 -> 0.14285714 | G3: =IFERROR(VLOOKUP(D3,SETTINGS!A14:B16,2,FALSE()),14) -> 14 | H3: =E3*(LeadTime+ReorderCycle+SafetyDays) -> 7.4285714 | I3: =F3*(LeadTime+ReorderCycle+SafetyDays) -> 1.8571429 | J3: =IF(D3="Slow",MIN(H3,SlowMoverCap),H3) -> 7.4285714 | K3: =IF(D3="Slow",MIN(I3,SlowMoverCap),I3) -> 1.8571429
A4: =DEMAND_MODEL!A4 -> 3 | B4: =DEMAND_MODEL!B4 -> 62963 | C4: =DEMAND_MODEL!C4 -> ICING PRE-WHIPPED VANILLA 6.8K | D4: =DEMAND_MODEL!G4 -> Medium | E4: =DEMAND_MODEL!K4 -> 0.28571429 | F4: =DEMAND_MODEL!L4 -> 0.28571429 | G4: =IFERROR(VLOOKUP(D4,SETTINGS!A14:B16,2,FALSE()),14) -> 14 | H4: =E4*(LeadTime+ReorderCycle+SafetyDays) -> 3.7142857 | I4: =F4*(LeadTime+ReorderCycle+SafetyDays) -> 3.7142857 | J4: =IF(D4="Slow",MIN(H4,SlowMoverCap),H4) -> 3.7142857 | K4: =IF(D4="Slow",MIN(I4,SlowMoverCap),I4) -> 3.7142857
A5: =DEMAND_MODEL!A5 -> 4 | B5: =DEMAND_MODEL!B5 -> 22400 | C5: =DEMAND_MODEL!C5 -> LADIP LABEL CHOCOLATE CAKE 1RLX50UN | D5: =DEMAND_MODEL!G5 -> Medium | E5: =DEMAND_MODEL!K5 -> 0.42857143 | F5: =DEMAND_MODEL!L5 -> 0.14285714 | G5: =IFERROR(VLOOKUP(D5,SETTINGS!A14:B16,2,FALSE()),14) -> 14 | H5: =E5*(LeadTime+ReorderCycle+SafetyDays) -> 5.5714286 | I5: =F5*(LeadTime+ReorderCycle+SafetyDays) -> 1.8571429 | J5: =IF(D5="Slow",MIN(H5,SlowMoverCap),H5) -> 5.5714286 | K5: =IF(D5="Slow",MIN(I5,SlowMoverCap),I5) -> 1.8571429
A6: =DEMAND_MODEL!A6 -> 5 | B6: =DEMAND_MODEL!B6 -> 22401 | C6: =DEMAND_MODEL!C6 -> LADIP LABEL BIRTHDAY CAKE 1RLX50UN | D6: =DEMAND_MODEL!G6 -> Medium | E6: =DEMAND_MODEL!K6 -> 0.57142857 | F6: =DEMAND_MODEL!L6 -> 0.14285714 | G6: =IFERROR(VLOOKUP(D6,SETTINGS!A14:B16,2,FALSE()),14) -> 14 | H6: =E6*(LeadTime+ReorderCycle+SafetyDays) -> 7.4285714 | I6: =F6*(LeadTime+ReorderCycle+SafetyDays) -> 1.8571429 | J6: =IF(D6="Slow",MIN(H6,SlowMoverCap),H6) -> 7.4285714 | K6: =IF(D6="Slow",MIN(I6,SlowMoverCap),I6) -> 1.8571429
A7: =DEMAND_MODEL!A7 -> 6 | B7: =DEMAND_MODEL!B7 -> 22402 | C7: =DEMAND_MODEL!C7 -> LADIP LABEL COOKIE & CREAM CAKE 1RL | D7: =DEMAND_MODEL!G7 -> Medium | E7: =DEMAND_MODEL!K7 -> 0.28571429 | F7: =DEMAND_MODEL!L7 -> 0.28571429 | G7: =IFERROR(VLOOKUP(D7,SETTINGS!A14:B16,2,FALSE()),14) -> 14 | H7: =E7*(LeadTime+ReorderCycle+SafetyDays) -> 3.7142857 | I7: =F7*(LeadTime+ReorderCycle+SafetyDays) -> 3.7142857 | J7: =IF(D7="Slow",MIN(H7,SlowMoverCap),H7) -> 3.7142857 | K7: =IF(D7="Slow",MIN(I7,SlowMoverCap),I7) -> 3.7142857
A8: =DEMAND_MODEL!A8 -> 7 | B8: =DEMAND_MODEL!B8 -> 22406 | C8: =DEMAND_MODEL!C8 -> LADIP LABEL SALTD CARAMEL CAKE 1RL | D8: =DEMAND_MODEL!G8 -> Medium | E8: =DEMAND_MODEL!K8 -> 0.42857143 | F8: =DEMAND_MODEL!L8 -> 0.14285714 | G8: =IFERROR(VLOOKUP(D8,SETTINGS!A14:B16,2,FALSE()),14) -> 14 | H8: =E8*(LeadTime+ReorderCycle+SafetyDays) -> 5.5714286 | I8: =F8*(LeadTime+ReorderCycle+SafetyDays) -> 1.8571429 | J8: =IF(D8="Slow",MIN(H8,SlowMoverCap),H8) -> 5.5714286 | K8: =IF(D8="Slow",MIN(I8,SlowMoverCap),I8) -> 1.8571429
A9: =DEMAND_MODEL!A9 -> 8 | B9: =DEMAND_MODEL!B9 -> 22407 | C9: =DEMAND_MODEL!C9 -> LADIP LABEL STRABERRY CAKE 1RLX50UN | D9: =DEMAND_MODEL!G9 -> Medium | E9: =DEMAND_MODEL!K9 -> 0.42857143 | F9: =DEMAND_MODEL!L9 -> 0.42857143 | G9: =IFERROR(VLOOKUP(D9,SETTINGS!A14:B16,2,FALSE()),14) -> 14 | H9: =E9*(LeadTime+ReorderCycle+SafetyDays) -> 5.5714286 | I9: =F9*(LeadTime+ReorderCycle+SafetyDays) -> 5.5714286 | J9: =IF(D9="Slow",MIN(H9,SlowMoverCap),H9) -> 5.5714286 | K9: =IF(D9="Slow",MIN(I9,SlowMoverCap),I9) -> 5.5714286
A10: =DEMAND_MODEL!A10 -> 9 | B10: =DEMAND_MODEL!B10 -> 25800 | C10: =DEMAND_MODEL!C10 -> CAKE CARDBOARD 8" BLCK GOLD 100 | D10: =DEMAND_MODEL!G10 -> Medium | E10: =DEMAND_MODEL!K10 -> 0.42857143 | F10: =DEMAND_MODEL!L10 -> 0.14285714 | G10: =IFERROR(VLOOKUP(D10,SETTINGS!A14:B16,2,FALSE()),14) -> 14 | H10: =E10*(LeadTime+ReorderCycle+SafetyDays) -> 5.5714286 | I10: =F10*(LeadTime+ReorderCycle+SafetyDays) -> 1.8571429 | J10: =IF(D10="Slow",MIN(H10,SlowMoverCap),H10) -> 5.5714286 | K10: =IF(D10="Slow",MIN(I10,SlowMoverCap),I10) -> 1.8571429
A11: =DEMAND_MODEL!A11 -> 10 | B11: =DEMAND_MODEL!B11 -> 25802 | C11: =DEMAND_MODEL!C11 -> ACETATE ROLL 3.5"X1250" 4MM 1RL | D11: =DEMAND_MODEL!G11 -> Medium | E11: =DEMAND_MODEL!K11 -> 0.42857143 | F11: =DEMAND_MODEL!L11 -> 0.42857143 | G11: =IFERROR(VLOOKUP(D11,SETTINGS!A14:B16,2,FALSE()),14) -> 14 | H11: =E11*(LeadTime+ReorderCycle+SafetyDays) -> 5.5714286 | I11: =F11*(LeadTime+ReorderCycle+SafetyDays) -> 5.5714286 | J11: =IF(D11="Slow",MIN(H11,SlowMoverCap),H11) -> 5.5714286 | K11: =IF(D11="Slow",MIN(I11,SlowMoverCap),I11) -> 5.5714286
A12: =DEMAND_MODEL!A12 -> 11 | B12: =DEMAND_MODEL!B12 -> 19689 | C12: =DEMAND_MODEL!C12 -> CAKE CUPCAKE BLACKOUT 8X4UN | D12: =DEMAND_MODEL!G12 -> Medium | E12: =DEMAND_MODEL!K12 -> 0.14285714 | F12: =DEMAND_MODEL!L12 -> 0.14285714 | G12: =IFERROR(VLOOKUP(D12,SETTINGS!A14:B16,2,FALSE()),14) -> 14 | H12: =E12*(LeadTime+ReorderCycle+SafetyDays) -> 1.8571429 | I12: =F12*(LeadTime+ReorderCycle+SafetyDays) -> 1.8571429 | J12: =IF(D12="Slow",MIN(H12,SlowMoverCap),H12) -> 1.8571429 | K12: =IF(D12="Slow",MIN(I12,SlowMoverCap),I12) -> 1.8571429
A13: =DEMAND_MODEL!A13 -> 12 | B13: =DEMAND_MODEL!B13 -> 19692 | C13: =DEMAND_MODEL!C13 -> CAKE CUPCAKE RED VELVET 8X4UN | D13: =DEMAND_MODEL!G13 -> Medium | E13: =DEMAND_MODEL!K13 -> 0.28571429 | F13: =DEMAND_MODEL!L13 -> 0.14285714 | G13: =IFERROR(VLOOKUP(D13,SETTINGS!A14:B16,2,FALSE()),14) -> 14 | H13: =E13*(LeadTime+ReorderCycle+SafetyDays) -> 3.7142857 | I13: =F13*(LeadTime+ReorderCycle+SafetyDays) -> 1.8571429 | J13: =IF(D13="Slow",MIN(H13,SlowMoverCap),H13) -> 3.7142857 | K13: =IF(D13="Slow",MIN(I13,SlowMoverCap),I13) -> 1.8571429
A14: =DEMAND_MODEL!A14 -> 13 | B14: =DEMAND_MODEL!B14 -> 19693 | C14: =DEMAND_MODEL!C14 -> CAKE CUPCAKE VANILLA BEAN 8X4UN | D14: =DEMAND_MODEL!G14 -> Medium | E14: =DEMAND_MODEL!K14 -> 0.14285714 | F14: =DEMAND_MODEL!L14 -> 0.28571429 | G14: =IFERROR(VLOOKUP(D14,SETTINGS!A14:B16,2,FALSE()),14) -> 14 | H14: =E14*(LeadTime+ReorderCycle+SafetyDays) -> 1.8571429 | I14: =F14*(LeadTime+ReorderCycle+SafetyDays) -> 3.7142857 | J14: =IF(D14="Slow",MIN(H14,SlowMoverCap),H14) -> 1.8571429 | K14: =IF(D14="Slow",MIN(I14,SlowMoverCap),I14) -> 3.7142857
A15: =DEMAND_MODEL!A15 -> 14 | B15: =DEMAND_MODEL!B15 -> 19688 | C15: =DEMAND_MODEL!C15 -> CAKE CHEESE ORIGINAL 6X6" | D15: =DEMAND_MODEL!G15 -> Medium | E15: =DEMAND_MODEL!K15 -> 0.14285714 | F15: =DEMAND_MODEL!L15 -> 0.28571429 | G15: =IFERROR(VLOOKUP(D15,SETTINGS!A14:B16,2,FALSE()),14) -> 14 | H15: =E15*(LeadTime+ReorderCycle+SafetyDays) -> 1.8571429 | I15: =F15*(LeadTime+ReorderCycle+SafetyDays) -> 3.7142857 | J15: =IF(D15="Slow",MIN(H15,SlowMoverCap),H15) -> 1.8571429 | K15: =IF(D15="Slow",MIN(I15,SlowMoverCap),I15) -> 3.7142857
A16: =DEMAND_MODEL!A16 -> 15 | B16: =DEMAND_MODEL!B16 -> 19687 | C16: =DEMAND_MODEL!C16 -> CAKE CHEESE WHT CHOC/RASP 6X6" | D16: =DEMAND_MODEL!G16 -> Medium | E16: =DEMAND_MODEL!K16 -> 0.42857143 | F16: =DEMAND_MODEL!L16 -> 0.28571429 | G16: =IFERROR(VLOOKUP(D16,SETTINGS!A14:B16,2,FALSE()),14) -> 14 | H16: =E16*(LeadTime+ReorderCycle+SafetyDays) -> 5.5714286 | I16: =F16*(LeadTime+ReorderCycle+SafetyDays) -> 3.7142857 | J16: =IF(D16="Slow",MIN(H16,SlowMoverCap),H16) -> 5.5714286 | K16: =IF(D16="Slow",MIN(I16,SlowMoverCap),I16) -> 3.7142857
A17: =DEMAND_MODEL!A17 -> 16 | B17: =DEMAND_MODEL!B17 -> 19685 | C17: =DEMAND_MODEL!C17 -> CAKE CHEESE CHOC MOUSSE 6X6" | D17: =DEMAND_MODEL!G17 -> Medium | E17: =DEMAND_MODEL!K17 -> 0.14285714 | F17: =DEMAND_MODEL!L17 -> 0.14285714 | G17: =IFERROR(VLOOKUP(D17,SETTINGS!A14:B16,2,FALSE()),14) -> 14 | H17: =E17*(LeadTime+ReorderCycle+SafetyDays) -> 1.8571429 | I17: =F17*(LeadTime+ReorderCycle+SafetyDays) -> 1.8571429 | J17: =IF(D17="Slow",MIN(H17,SlowMoverCap),H17) -> 1.8571429 | K17: =IF(D17="Slow",MIN(I17,SlowMoverCap),I17) -> 1.8571429
A18: =DEMAND_MODEL!A18 -> 17 | B18: =DEMAND_MODEL!B18 -> 19628 | C18: =DEMAND_MODEL!C18 -> CAKE CHEESE CAKE FACTORY 2X14UN | D18: =DEMAND_MODEL!G18 -> Medium | E18: =DEMAND_MODEL!K18 -> 0.28571429 | F18: =DEMAND_MODEL!L18 -> 0.14285714 | G18: =IFERROR(VLOOKUP(D18,SETTINGS!A14:B16,2,FALSE()),14) -> 14 | H18: =E18*(LeadTime+ReorderCycle+SafetyDays) -> 3.7142857 | I18: =F18*(LeadTime+ReorderCycle+SafetyDays) -> 1.8571429 | J18: =IF(D18="Slow",MIN(H18,SlowMoverCap),H18) -> 3.7142857 | K18: =IF(D18="Slow",MIN(I18,SlowMoverCap),I18) -> 1.8571429
A19: =DEMAND_MODEL!A19 -> 18 | B19: =DEMAND_MODEL!B19 -> 16992 | C19: =DEMAND_MODEL!C19 -> CAKE CHEESE MANGO LIME X2 | D19: =DEMAND_MODEL!G19 -> Medium | E19: =DEMAND_MODEL!K19 -> 0.14285714 | F19: =DEMAND_MODEL!L19 -> 0.28571429 | G19: =IFERROR(VLOOKUP(D19,SETTINGS!A14:B16,2,FALSE()),14) -> 14 | H19: =E19*(LeadTime+ReorderCycle+SafetyDays) -> 1.8571429 | I19: =F19*(LeadTime+ReorderCycle+SafetyDays) -> 3.7142857 | J19: =IF(D19="Slow",MIN(H19,SlowMoverCap),H19) -> 1.8571429 | K19: =IF(D19="Slow",MIN(I19,SlowMoverCap),I19) -> 3.7142857
A20: =DEMAND_MODEL!A20 -> 19 | B20: =DEMAND_MODEL!B20 -> 16995 | C20: =DEMAND_MODEL!C20 -> CAKE CHEESE CINNABON X2 | D20: =DEMAND_MODEL!G20 -> Medium | E20: =DEMAND_MODEL!K20 -> 0.14285714 | F20: =DEMAND_MODEL!L20 -> 0.28571429 | G20: =IFERROR(VLOOKUP(D20,SETTINGS!A14:B16,2,FALSE()),14) -> 14 | H20: =E20*(LeadTime+ReorderCycle+SafetyDays) -> 1.8571429 | I20: =F20*(LeadTime+ReorderCycle+SafetyDays) -> 3.7142857 | J20: =IF(D20="Slow",MIN(H20,SlowMoverCap),H20) -> 1.8571429 | K20: =IF(D20="Slow",MIN(I20,SlowMoverCap),I20) -> 3.7142857
A21: =DEMAND_MODEL!A21 -> 20 | B21: =DEMAND_MODEL!B21 -> 19629 | C21: =DEMAND_MODEL!C21 -> CAKE GODIVA DBL CHOC CHEESE 2X28PC | D21: =DEMAND_MODEL!G21 -> Medium | E21: =DEMAND_MODEL!K21 -> 0.14285714 | F21: =DEMAND_MODEL!L21 -> 0.28571429 | G21: =IFERROR(VLOOKUP(D21,SETTINGS!A14:B16,2,FALSE()),14) -> 14 | H21: =E21*(LeadTime+ReorderCycle+SafetyDays) -> 1.8571429 | I21: =F21*(LeadTime+ReorderCycle+SafetyDays) -> 3.7142857 | J21: =IF(D21="Slow",MIN(H21,SlowMoverCap),H21) -> 1.8571429 | K21: =IF(D21="Slow",MIN(I21,SlowMoverCap),I21) -> 3.7142857
A22: =DEMAND_MODEL!A22 -> 21 | B22: =DEMAND_MODEL!B22 -> 16993 | C22: =DEMAND_MODEL!C22 -> CAKE CHEESE OREO X2 | D22: =DEMAND_MODEL!G22 -> Medium | E22: =DEMAND_MODEL!K22 -> 0.28571429 | F22: =DEMAND_MODEL!L22 -> 0.28571429 | G22: =IFERROR(VLOOKUP(D22,SETTINGS!A14:B16,2,FALSE()),14) -> 14 | H22: =E22*(LeadTime+ReorderCycle+SafetyDays) -> 3.7142857 | I22: =F22*(LeadTime+ReorderCycle+SafetyDays) -> 3.7142857 | J22: =IF(D22="Slow",MIN(H22,SlowMoverCap),H22) -> 3.7142857 | K22: =IF(D22="Slow",MIN(I22,SlowMoverCap),I22) -> 3.7142857
A23: =DEMAND_MODEL!A23 -> 22 | B23: =DEMAND_MODEL!B23 -> 16988 | C23: =DEMAND_MODEL!C23 -> CAKE CHEESE BANANA FOSTER X2 | D23: =DEMAND_MODEL!G23 -> Medium | E23: =DEMAND_MODEL!K23 -> 0.42857143 | F23: =DEMAND_MODEL!L23 -> 0.14285714 | G23: =IFERROR(VLOOKUP(D23,SETTINGS!A14:B16,2,FALSE()),14) -> 14 | H23: =E23*(LeadTime+ReorderCycle+SafetyDays) -> 5.5714286 | I23: =F23*(LeadTime+ReorderCycle+SafetyDays) -> 1.8571429 | J23: =IF(D23="Slow",MIN(H23,SlowMoverCap),H23) -> 5.5714286 | K23: =IF(D23="Slow",MIN(I23,SlowMoverCap),I23) -> 1.8571429
A24: =DEMAND_MODEL!A24 -> 23 | B24: =DEMAND_MODEL!B24 -> 16987 | C24: =DEMAND_MODEL!C24 -> CAKE CHEESE WILD STRWBERRY X2 | D24: =DEMAND_MODEL!G24 -> Medium | E24: =DEMAND_MODEL!K24 -> 0.14285714 | F24: =DEMAND_MODEL!L24 -> 0.28571429 | G24: =IFERROR(VLOOKUP(D24,SETTINGS!A14:B16,2,FALSE()),14) -> 14 | H24: =E24*(LeadTime+ReorderCycle+SafetyDays) -> 1.8571429 | I24: =F24*(LeadTime+ReorderCycle+SafetyDays) -> 3.7142857 | J24: =IF(D24="Slow",MIN(H24,SlowMoverCap),H24) -> 1.8571429 | K24: =IF(D24="Slow",MIN(I24,SlowMoverCap),I24) -> 3.7142857
A25: =DEMAND_MODEL!A25 -> 24 | B25: =DEMAND_MODEL!B25 -> 16994 | C25: =DEMAND_MODEL!C25 -> CAKE CHEESE DULCE DE LECHE X2 | D25: =DEMAND_MODEL!G25 -> Medium | E25: =DEMAND_MODEL!K25 -> 0.42857143 | F25: =DEMAND_MODEL!L25 -> 0.14285714 | G25: =IFERROR(VLOOKUP(D25,SETTINGS!A14:B16,2,FALSE()),14) -> 14 | H25: =E25*(LeadTime+ReorderCycle+SafetyDays) -> 5.5714286 | I25: =F25*(LeadTime+ReorderCycle+SafetyDays) -> 1.8571429 | J25: =IF(D25="Slow",MIN(H25,SlowMoverCap),H25) -> 5.5714286 | K25: =IF(D25="Slow",MIN(I25,SlowMoverCap),I25) -> 1.8571429
A26: =DEMAND_MODEL!A26 -> 25 | B26: =DEMAND_MODEL!B26 -> 19694 | C26: =DEMAND_MODEL!C26 -> CAKE REESE P.BUTTER CHOC 2X28PC | D26: =DEMAND_MODEL!G26 -> Medium | E26: =DEMAND_MODEL!K26 -> 0.14285714 | F26: =DEMAND_MODEL!L26 -> 0.14285714 | G26: =IFERROR(VLOOKUP(D26,SETTINGS!A14:B16,2,FALSE()),14) -> 14 | H26: =E26*(LeadTime+ReorderCycle+SafetyDays) -> 1.8571429 | I26: =F26*(LeadTime+ReorderCycle+SafetyDays) -> 1.8571429 | J26: =IF(D26="Slow",MIN(H26,SlowMoverCap),H26) -> 1.8571429 | K26: =IF(D26="Slow",MIN(I26,SlowMoverCap),I26) -> 1.8571429
A27: =DEMAND_MODEL!A27 -> 26 | B27: =DEMAND_MODEL!B27 -> 16991 | C27: =DEMAND_MODEL!C27 -> CAKE CHEESE RED VELVET X2 | D27: =DEMAND_MODEL!G27 -> Medium | E27: =DEMAND_MODEL!K27 -> 0.42857143 | F27: =DEMAND_MODEL!L27 -> 0.28571429 | G27: =IFERROR(VLOOKUP(D27,SETTINGS!A14:B16,2,FALSE()),14) -> 14 | H27: =E27*(LeadTime+ReorderCycle+SafetyDays) -> 5.5714286 | I27: =F27*(LeadTime+ReorderCycle+SafetyDays) -> 3.7142857 | J27: =IF(D27="Slow",MIN(H27,SlowMoverCap),H27) -> 5.5714286 | K27: =IF(D27="Slow",MIN(I27,SlowMoverCap),I27) -> 3.7142857
A28: =DEMAND_MODEL!A28 -> 27 | B28: =DEMAND_MODEL!B28 -> 16989 | C28: =DEMAND_MODEL!C28 -> CAKE CHEESE TUXEDO MOUSSE X2 | D28: =DEMAND_MODEL!G28 -> Medium | E28: =DEMAND_MODEL!K28 -> 0.14285714 | F28: =DEMAND_MODEL!L28 -> 0.14285714 | G28: =IFERROR(VLOOKUP(D28,SETTINGS!A14:B16,2,FALSE()),14) -> 14 | H28: =E28*(LeadTime+ReorderCycle+SafetyDays) -> 1.8571429 | I28: =F28*(LeadTime+ReorderCycle+SafetyDays) -> 1.8571429 | J28: =IF(D28="Slow",MIN(H28,SlowMoverCap),H28) -> 1.8571429 | K28: =IF(D28="Slow",MIN(I28,SlowMoverCap),I28) -> 1.8571429
A29: =DEMAND_MODEL!A29 -> 28 | B29: =DEMAND_MODEL!B29 -> 19630 | C29: =DEMAND_MODEL!C29 -> CAKE WHITE CHOC RSPBRY CHEESE X2 | D29: =DEMAND_MODEL!G29 -> Medium | E29: =DEMAND_MODEL!K29 -> 0.42857143 | F29: =DEMAND_MODEL!L29 -> 0.14285714 | G29: =IFERROR(VLOOKUP(D29,SETTINGS!A14:B16,2,FALSE()),14) -> 14 | H29: =E29*(LeadTime+ReorderCycle+SafetyDays) -> 5.5714286 | I29: =F29*(LeadTime+ReorderCycle+SafetyDays) -> 1.8571429 | J29: =IF(D29="Slow",MIN(H29,SlowMoverCap),H29) -> 5.5714286 | K29: =IF(D29="Slow",MIN(I29,SlowMoverCap),I29) -> 1.8571429
A30: =DEMAND_MODEL!A30 -> 29 | B30: =DEMAND_MODEL!B30 -> 44985 | C30: =DEMAND_MODEL!C30 -> BISC DOUGH OREO V-VIT0013V 5K | D30: =DEMAND_MODEL!G30 -> Fast | E30: =DEMAND_MODEL!K30 -> 0.85714286 | F30: =DEMAND_MODEL!L30 -> 0.14285714 | G30: =IFERROR(VLOOKUP(D30,SETTINGS!A14:B16,2,FALSE()),14) -> 21 | H30: =E30*(LeadTime+ReorderCycle+SafetyDays) -> 11.142857 | I30: =F30*(LeadTime+ReorderCycle+SafetyDays) -> 1.8571429 | J30: =IF(D30="Slow",MIN(H30,SlowMoverCap),H30) -> 11.142857 | K30: =IF(D30="Slow",MIN(I30,SlowMoverCap),I30) -> 1.8571429
A31: =DEMAND_MODEL!A31 -> 30 | B31: =DEMAND_MODEL!B31 -> 44961 | C31: =DEMAND_MODEL!C31 -> BISC DOUGH BLK CHOCO MED SWEET 5K | D31: =DEMAND_MODEL!G31 -> Fast | E31: =DEMAND_MODEL!K31 -> 0.42857143 | F31: =DEMAND_MODEL!L31 -> 0.42857143 | G31: =IFERROR(VLOOKUP(D31,SETTINGS!A14:B16,2,FALSE()),14) -> 21 | H31: =E31*(LeadTime+ReorderCycle+SafetyDays) -> 5.5714286 | I31: =F31*(LeadTime+ReorderCycle+SafetyDays) -> 5.5714286 | J31: =IF(D31="Slow",MIN(H31,SlowMoverCap),H31) -> 5.5714286 | K31: =IF(D31="Slow",MIN(I31,SlowMoverCap),I31) -> 5.5714286
A32: =DEMAND_MODEL!A32 -> 31 | B32: =DEMAND_MODEL!B32 -> 44962 | C32: =DEMAND_MODEL!C32 -> BISC DOUGH DBL CHOCO PAIL 5K | D32: =DEMAND_MODEL!G32 -> Fast | E32: =DEMAND_MODEL!K32 -> 0.85714286 | F32: =DEMAND_MODEL!L32 -> 0.14285714 | G32: =IFERROR(VLOOKUP(D32,SETTINGS!A14:B16,2,FALSE()),14) -> 21 | H32: =E32*(LeadTime+ReorderCycle+SafetyDays) -> 11.142857 | I32: =F32*(LeadTime+ReorderCycle+SafetyDays) -> 1.8571429 | J32: =IF(D32="Slow",MIN(H32,SlowMoverCap),H32) -> 11.142857 | K32: =IF(D32="Slow",MIN(I32,SlowMoverCap),I32) -> 1.8571429
A33: =DEMAND_MODEL!A33 -> 32 | B33: =DEMAND_MODEL!B33 -> 63927 | C33: =DEMAND_MODEL!C33 -> Bisc PUCK Dbl Choc 160x2oz | D33: =DEMAND_MODEL!G33 -> Fast | E33: =DEMAND_MODEL!K33 -> 0.57142857 | F33: =DEMAND_MODEL!L33 -> 0.42857143 | G33: =IFERROR(VLOOKUP(D33,SETTINGS!A14:B16,2,FALSE()),14) -> 21 | H33: =E33*(LeadTime+ReorderCycle+SafetyDays) -> 7.4285714 | I33: =F33*(LeadTime+ReorderCycle+SafetyDays) -> 5.5714286 | J33: =IF(D33="Slow",MIN(H33,SlowMoverCap),H33) -> 7.4285714 | K33: =IF(D33="Slow",MIN(I33,SlowMoverCap),I33) -> 5.5714286
A34: =DEMAND_MODEL!A34 -> 33 | B34: =DEMAND_MODEL!B34 -> 64106 | C34: =DEMAND_MODEL!C34 -> Bisc PUCK ChocBln/Maca 160x2oz | D34: =DEMAND_MODEL!G34 -> Fast | E34: =DEMAND_MODEL!K34 -> 0.28571429 | F34: =DEMAND_MODEL!L34 -> 0.42857143 | G34: =IFERROR(VLOOKUP(D34,SETTINGS!A14:B16,2,FALSE()),14) -> 21 | H34: =E34*(LeadTime+ReorderCycle+SafetyDays) -> 3.7142857 | I34: =F34*(LeadTime+ReorderCycle+SafetyDays) -> 5.5714286 | J34: =IF(D34="Slow",MIN(H34,SlowMoverCap),H34) -> 3.7142857 | K34: =IF(D34="Slow",MIN(I34,SlowMoverCap),I34) -> 5.5714286
A35: =DEMAND_MODEL!A35 -> 34 | B35: =DEMAND_MODEL!B35 -> 63934 | C35: =DEMAND_MODEL!C35 -> Bisc PUCK ChocChunk 160x2oz | D35: =DEMAND_MODEL!G35 -> Fast | E35: =DEMAND_MODEL!K35 -> 0.42857143 | F35: =DEMAND_MODEL!L35 -> 0.42857143 | G35: =IFERROR(VLOOKUP(D35,SETTINGS!A14:B16,2,FALSE()),14) -> 21 | H35: =E35*(LeadTime+ReorderCycle+SafetyDays) -> 5.5714286 | I35: =F35*(LeadTime+ReorderCycle+SafetyDays) -> 5.5714286 | J35: =IF(D35="Slow",MIN(H35,SlowMoverCap),H35) -> 5.5714286 | K35: =IF(D35="Slow",MIN(I35,SlowMoverCap),I35) -> 5.5714286
A36: =DEMAND_MODEL!A36 -> 35 | B36: =DEMAND_MODEL!B36 -> 12596 | C36: =DEMAND_MODEL!C36 -> MTY TREAT FOR DOGS 24UN | D36: =DEMAND_MODEL!G36 -> Fast | E36: =DEMAND_MODEL!K36 -> 0.57142857 | F36: =DEMAND_MODEL!L36 -> 0.14285714 | G36: =IFERROR(VLOOKUP(D36,SETTINGS!A14:B16,2,FALSE()),14) -> 21 | H36: =E36*(LeadTime+ReorderCycle+SafetyDays) -> 7.4285714 | I36: =F36*(LeadTime+ReorderCycle+SafetyDays) -> 1.8571429 | J36: =IF(D36="Slow",MIN(H36,SlowMoverCap),H36) -> 7.4285714 | K36: =IF(D36="Slow",MIN(I36,SlowMoverCap),I36) -> 1.8571429
A37: =DEMAND_MODEL!A37 -> 36 | B37: =DEMAND_MODEL!B37 -> 48219 | C37: =DEMAND_MODEL!C37 -> BISC LOTUS BISCOFF 10X250G | D37: =DEMAND_MODEL!G37 -> Fast | E37: =DEMAND_MODEL!K37 -> 0.71428571 | F37: =DEMAND_MODEL!L37 -> 0.57142857 | G37: =IFERROR(VLOOKUP(D37,SETTINGS!A14:B16,2,FALSE()),14) -> 21 | H37: =E37*(LeadTime+ReorderCycle+SafetyDays) -> 9.2857143 | I37: =F37*(LeadTime+ReorderCycle+SafetyDays) -> 7.4285714 | J37: =IF(D37="Slow",MIN(H37,SlowMoverCap),H37) -> 9.2857143 | K37: =IF(D37="Slow",MIN(I37,SlowMoverCap),I37) -> 7.4285714
A38: =DEMAND_MODEL!A38 -> 37 | B38: =DEMAND_MODEL!B38 -> 39811 | C38: =DEMAND_MODEL!C38 -> DONUT REGULAR 00726 140X28G | D38: =DEMAND_MODEL!G38 -> Medium | E38: =DEMAND_MODEL!K38 -> 0.57142857 | F38: =DEMAND_MODEL!L38 -> 0.14285714 | G38: =IFERROR(VLOOKUP(D38,SETTINGS!A14:B16,2,FALSE()),14) -> 14 | H38: =E38*(LeadTime+ReorderCycle+SafetyDays) -> 7.4285714 | I38: =F38*(LeadTime+ReorderCycle+SafetyDays) -> 1.8571429 | J38: =IF(D38="Slow",MIN(H38,SlowMoverCap),H38) -> 7.4285714 | K38: =IF(D38="Slow",MIN(I38,SlowMoverCap),I38) -> 1.8571429
A39: =DEMAND_MODEL!A39 -> 38 | B39: =DEMAND_MODEL!B39 -> 43328 | C39: =DEMAND_MODEL!C39 -> DONUT MINI VANILLA 2442 300X12G | D39: =DEMAND_MODEL!G39 -> Medium | E39: =DEMAND_MODEL!K39 -> 0.42857143 | F39: =DEMAND_MODEL!L39 -> 0.42857143 | G39: =IFERROR(VLOOKUP(D39,SETTINGS!A14:B16,2,FALSE()),14) -> 14 | H39: =E39*(LeadTime+ReorderCycle+SafetyDays) -> 5.5714286 | I39: =F39*(LeadTime+ReorderCycle+SafetyDays) -> 5.5714286 | J39: =IF(D39="Slow",MIN(H39,SlowMoverCap),H39) -> 5.5714286 | K39: =IF(D39="Slow",MIN(I39,SlowMoverCap),I39) -> 5.5714286
A40: =DEMAND_MODEL!A40 -> 39 | B40: =DEMAND_MODEL!B40 -> 50170 | C40: =DEMAND_MODEL!C40 -> MTY CHOC FF 3100051 5X1L | D40: =DEMAND_MODEL!G40 -> Medium | E40: =DEMAND_MODEL!K40 -> 0.28571429 | F40: =DEMAND_MODEL!L40 -> 0.28571429 | G40: =IFERROR(VLOOKUP(D40,SETTINGS!A14:B16,2,FALSE()),14) -> 14 | H40: =E40*(LeadTime+ReorderCycle+SafetyDays) -> 3.7142857 | I40: =F40*(LeadTime+ReorderCycle+SafetyDays) -> 3.7142857 | J40: =IF(D40="Slow",MIN(H40,SlowMoverCap),H40) -> 3.7142857 | K40: =IF(D40="Slow",MIN(I40,SlowMoverCap),I40) -> 3.7142857
...

Sheet REBALANCE_PLAN
A1: # | B1: Code | C1: Description | D1: Unit Cost | E1: On-Hand OAK | F1: On-Hand HP | G1: Par OAK | H1: Par HP | I1: Surplus OAK | J1: Surplus HP | K1: Deficit OAK | L1: Deficit HP | M1: Transfer Direction | N1: Transfer Qty | O1: Purchase OAK (units) | P1: Purchase HP (units) | Q1: Purchase OAK (cases) | R1: Purchase HP (cases) | S1: Priority Score
A2: =ITEM_MASTER_CLEAN!A2 -> 1 | B2: =ITEM_MASTER_CLEAN!B2 -> 62966 | C2: =ITEM_MASTER_CLEAN!C2 -> 9 CAKE WHITE LAYER 8" 24X354G | D2: =ITEM_MASTER_CLEAN!F2 -> 60.84 | E2: =ITEM_MASTER_CLEAN!H2 -> 1 | F2: =ITEM_MASTER_CLEAN!I2 -> 5 | G2: =PAR_LEVELS!J2 -> 1.8571429 | H2: =PAR_LEVELS!K2 -> 5.5714286 | I2: =MAX(E2-G2,0) -> 0 | J2: =MAX(F2-H2,0) -> 0 | K2: =MAX(G2-E2,0) -> 0.85714286 | L2: =MAX(H2-F2,0) -> 0.57142857 | M2: =IF(AND(I2>TransferMin,L2>0),"OAK→HP",IF(AND(J2>TransferMin,K2>0),"HP→OAK","None")) -> None | N2: =IF(M2="OAK→HP",MIN(I2,L2),IF(M2="HP→OAK",MIN(J2,K2),0)) -> 0 | O2: =MAX(K2-IF(M2="HP→OAK",N2,0),0) -> 0.85714286 | P2: =MAX(L2-IF(M2="OAK→HP",N2,0),0) -> 0.57142857 | Q2: =IF(O2>0,CEILING(O2,ITEM_MASTER_CLEAN!G2),0) -> 24 | R2: =IF(P2>0,CEILING(P2,ITEM_MASTER_CLEAN!G2),0) -> 24 | S2: =IF(G2=0,0,(1-MIN(E2/MAX(G2,1),1))*50+(1-MIN(F2/MAX(H2,1),1))*50) -> 28.205128
A3: =ITEM_MASTER_CLEAN!A3 -> 2 | B3: =ITEM_MASTER_CLEAN!B3 -> 62967 | C3: =ITEM_MASTER_CLEAN!C3 -> 9 CAKE CHOC LAYER 8" 24X354G | D3: =ITEM_MASTER_CLEAN!F3 -> 23.82 | E3: =ITEM_MASTER_CLEAN!H3 -> 11 | F3: =ITEM_MASTER_CLEAN!I3 -> 0 | G3: =PAR_LEVELS!J3 -> 7.4285714 | H3: =PAR_LEVELS!K3 -> 1.8571429 | I3: =MAX(E3-G3,0) -> 3.5714286 | J3: =MAX(F3-H3,0) -> 0 | K3: =MAX(G3-E3,0) -> 0 | L3: =MAX(H3-F3,0) -> 1.8571429 | M3: =IF(AND(I3>TransferMin,L3>0),"OAK→HP",IF(AND(J3>TransferMin,K3>0),"HP→OAK","None")) -> None | N3: =IF(M3="OAK→HP",MIN(I3,L3),IF(M3="HP→OAK",MIN(J3,K3),0)) -> 0 | O3: =MAX(K3-IF(M3="HP→OAK",N3,0),0) -> 0 | P3: =MAX(L3-IF(M3="OAK→HP",N3,0),0) -> 1.8571429 | Q3: =IF(O3>0,CEILING(O3,ITEM_MASTER_CLEAN!G3),0) -> 0 | R3: =IF(P3>0,CEILING(P3,ITEM_MASTER_CLEAN!G3),0) -> 24 | S3: =IF(G3=0,0,(1-MIN(E3/MAX(G3,1),1))*50+(1-MIN(F3/MAX(H3,1),1))*50) -> 50
A4: =ITEM_MASTER_CLEAN!A4 -> 3 | B4: =ITEM_MASTER_CLEAN!B4 -> 62963 | C4: =ITEM_MASTER_CLEAN!C4 -> ICING PRE-WHIPPED VANILLA 6.8K | D4: =ITEM_MASTER_CLEAN!F4 -> 54.51 | E4: =ITEM_MASTER_CLEAN!H4 -> 9 | F4: =ITEM_MASTER_CLEAN!I4 -> 6 | G4: =PAR_LEVELS!J4 -> 3.7142857 | H4: =PAR_LEVELS!K4 -> 3.7142857 | I4: =MAX(E4-G4,0) -> 5.2857143 | J4: =MAX(F4-H4,0) -> 2.2857143 | K4: =MAX(G4-E4,0) -> 0 | L4: =MAX(H4-F4,0) -> 0 | M4: =IF(AND(I4>TransferMin,L4>0),"OAK→HP",IF(AND(J4>TransferMin,K4>0),"HP→OAK","None")) -> None | N4: =IF(M4="OAK→HP",MIN(I4,L4),IF(M4="HP→OAK",MIN(J4,K4),0)) -> 0 | O4: =MAX(K4-IF(M4="HP→OAK",N4,0),0) -> 0 | P4: =MAX(L4-IF(M4="OAK→HP",N4,0),0) -> 0 | Q4: =IF(O4>0,CEILING(O4,ITEM_MASTER_CLEAN!G4),0) -> 0 | R4: =IF(P4>0,CEILING(P4,ITEM_MASTER_CLEAN!G4),0) -> 0 | S4: =IF(G4=0,0,(1-MIN(E4/MAX(G4,1),1))*50+(1-MIN(F4/MAX(H4,1),1))*50) -> 0
A5: =ITEM_MASTER_CLEAN!A5 -> 4 | B5: =ITEM_MASTER_CLEAN!B5 -> 22400 | C5: =ITEM_MASTER_CLEAN!C5 -> LADIP LABEL CHOCOLATE CAKE 1RLX50UN | D5: =ITEM_MASTER_CLEAN!F5 -> 19.55 | E5: =ITEM_MASTER_CLEAN!H5 -> 4 | F5: =ITEM_MASTER_CLEAN!I5 -> 1 | G5: =PAR_LEVELS!J5 -> 5.5714286 | H5: =PAR_LEVELS!K5 -> 1.8571429 | I5: =MAX(E5-G5,0) -> 0 | J5: =MAX(F5-H5,0) -> 0 | K5: =MAX(G5-E5,0) -> 1.5714286 | L5: =MAX(H5-F5,0) -> 0.85714286 | M5: =IF(AND(I5>TransferMin,L5>0),"OAK→HP",IF(AND(J5>TransferMin,K5>0),"HP→OAK","None")) -> None | N5: =IF(M5="OAK→HP",MIN(I5,L5),IF(M5="HP→OAK",MIN(J5,K5),0)) -> 0 | O5: =MAX(K5-IF(M5="HP→OAK",N5,0),0) -> 1.5714286 | P5: =MAX(L5-IF(M5="OAK→HP",N5,0),0) -> 0.85714286 | Q5: =IF(O5>0,CEILING(O5,ITEM_MASTER_CLEAN!G5),0) -> 2 | R5: =IF(P5>0,CEILING(P5,ITEM_MASTER_CLEAN!G5),0) -> 1 | S5: =IF(G5=0,0,(1-MIN(E5/MAX(G5,1),1))*50+(1-MIN(F5/MAX(H5,1),1))*50) -> 37.179487
A6: =ITEM_MASTER_CLEAN!A6 -> 5 | B6: =ITEM_MASTER_CLEAN!B6 -> 22401 | C6: =ITEM_MASTER_CLEAN!C6 -> LADIP LABEL BIRTHDAY CAKE 1RLX50UN | D6: =ITEM_MASTER_CLEAN!F6 -> 23.36 | E6: =ITEM_MASTER_CLEAN!H6 -> 18 | F6: =ITEM_MASTER_CLEAN!I6 -> 4 | G6: =PAR_LEVELS!J6 -> 7.4285714 | H6: =PAR_LEVELS!K6 -> 1.8571429 | I6: =MAX(E6-G6,0) -> 10.571429 | J6: =MAX(F6-H6,0) -> 2.1428571 | K6: =MAX(G6-E6,0) -> 0 | L6: =MAX(H6-F6,0) -> 0 | M6: =IF(AND(I6>TransferMin,L6>0),"OAK→HP",IF(AND(J6>TransferMin,K6>0),"HP→OAK","None")) -> None | N6: =IF(M6="OAK→HP",MIN(I6,L6),IF(M6="HP→OAK",MIN(J6,K6),0)) -> 0 | O6: =MAX(K6-IF(M6="HP→OAK",N6,0),0) -> 0 | P6: =MAX(L6-IF(M6="OAK→HP",N6,0),0) -> 0 | Q6: =IF(O6>0,CEILING(O6,ITEM_MASTER_CLEAN!G6),0) -> 0 | R6: =IF(P6>0,CEILING(P6,ITEM_MASTER_CLEAN!G6),0) -> 0 | S6: =IF(G6=0,0,(1-MIN(E6/MAX(G6,1),1))*50+(1-MIN(F6/MAX(H6,1),1))*50) -> 0
A7: =ITEM_MASTER_CLEAN!A7 -> 6 | B7: =ITEM_MASTER_CLEAN!B7 -> 22402 | C7: =ITEM_MASTER_CLEAN!C7 -> LADIP LABEL COOKIE & CREAM CAKE 1RL | D7: =ITEM_MASTER_CLEAN!F7 -> 18.46 | E7: =ITEM_MASTER_CLEAN!H7 -> 3 | F7: =ITEM_MASTER_CLEAN!I7 -> 3 | G7: =PAR_LEVELS!J7 -> 3.7142857 | H7: =PAR_LEVELS!K7 -> 3.7142857 | I7: =MAX(E7-G7,0) -> 0 | J7: =MAX(F7-H7,0) -> 0 | K7: =MAX(G7-E7,0) -> 0.71428571 | L7: =MAX(H7-F7,0) -> 0.71428571 | M7: =IF(AND(I7>TransferMin,L7>0),"OAK→HP",IF(AND(J7>TransferMin,K7>0),"HP→OAK","None")) -> None | N7: =IF(M7="OAK→HP",MIN(I7,L7),IF(M7="HP→OAK",MIN(J7,K7),0)) -> 0 | O7: =MAX(K7-IF(M7="HP→OAK",N7,0),0) -> 0.71428571 | P7: =MAX(L7-IF(M7="OAK→HP",N7,0),0) -> 0.71428571 | Q7: =IF(O7>0,CEILING(O7,ITEM_MASTER_CLEAN!G7),0) -> 1 | R7: =IF(P7>0,CEILING(P7,ITEM_MASTER_CLEAN!G7),0) -> 1 | S7: =IF(G7=0,0,(1-MIN(E7/MAX(G7,1),1))*50+(1-MIN(F7/MAX(H7,1),1))*50) -> 19.230769
A8: =ITEM_MASTER_CLEAN!A8 -> 7 | B8: =ITEM_MASTER_CLEAN!B8 -> 22406 | C8: =ITEM_MASTER_CLEAN!C8 -> LADIP LABEL SALTD CARAMEL CAKE 1RL | D8: =ITEM_MASTER_CLEAN!F8 -> 19.63 | E8: =ITEM_MASTER_CLEAN!H8 -> 10 | F8: =ITEM_MASTER_CLEAN!I8 -> 0 | G8: =PAR_LEVELS!J8 -> 5.5714286 | H8: =PAR_LEVELS!K8 -> 1.8571429 | I8: =MAX(E8-G8,0) -> 4.4285714 | J8: =MAX(F8-H8,0) -> 0 | K8: =MAX(G8-E8,0) -> 0 | L8: =MAX(H8-F8,0) -> 1.8571429 | M8: =IF(AND(I8>TransferMin,L8>0),"OAK→HP",IF(AND(J8>TransferMin,K8>0),"HP→OAK","None")) -> None | N8: =IF(M8="OAK→HP",MIN(I8,L8),IF(M8="HP→OAK",MIN(J8,K8),0)) -> 0 | O8: =MAX(K8-IF(M8="HP→OAK",N8,0),0) -> 0 | P8: =MAX(L8-IF(M8="OAK→HP",N8,0),0) -> 1.8571429 | Q8: =IF(O8>0,CEILING(O8,ITEM_MASTER_CLEAN!G8),0) -> 0 | R8: =IF(P8>0,CEILING(P8,ITEM_MASTER_CLEAN!G8),0) -> 2 | S8: =IF(G8=0,0,(1-MIN(E8/MAX(G8,1),1))*50+(1-MIN(F8/MAX(H8,1),1))*50) -> 50
A9: =ITEM_MASTER_CLEAN!A9 -> 8 | B9: =ITEM_MASTER_CLEAN!B9 -> 22407 | C9: =ITEM_MASTER_CLEAN!C9 -> LADIP LABEL STRABERRY CAKE 1RLX50UN | D9: =ITEM_MASTER_CLEAN!F9 -> 22.62 | E9: =ITEM_MASTER_CLEAN!H9 -> 1 | F9: =ITEM_MASTER_CLEAN!I9 -> 11 | G9: =PAR_LEVELS!J9 -> 5.5714286 | H9: =PAR_LEVELS!K9 -> 5.5714286 | I9: =MAX(E9-G9,0) -> 0 | J9: =MAX(F9-H9,0) -> 5.4285714 | K9: =MAX(G9-E9,0) -> 4.5714286 | L9: =MAX(H9-F9,0) -> 0 | M9: =IF(AND(I9>TransferMin,L9>0),"OAK→HP",IF(AND(J9>TransferMin,K9>0),"HP→OAK","None")) -> HP→OAK | N9: =IF(M9="OAK→HP",MIN(I9,L9),IF(M9="HP→OAK",MIN(J9,K9),0)) -> 4.5714286 | O9: =MAX(K9-IF(M9="HP→OAK",N9,0),0) -> 0 | P9: =MAX(L9-IF(M9="OAK→HP",N9,0),0) -> 0 | Q9: =IF(O9>0,CEILING(O9,ITEM_MASTER_CLEAN!G9),0) -> 0 | R9: =IF(P9>0,CEILING(P9,ITEM_MASTER_CLEAN!G9),0) -> 0 | S9: =IF(G9=0,0,(1-MIN(E9/MAX(G9,1),1))*50+(1-MIN(F9/MAX(H9,1),1))*50) -> 41.025641
A10: =ITEM_MASTER_CLEAN!A10 -> 9 | B10: =ITEM_MASTER_CLEAN!B10 -> 25800 | C10: =ITEM_MASTER_CLEAN!C10 -> CAKE CARDBOARD 8" BLCK GOLD 100 | D10: =ITEM_MASTER_CLEAN!F10 -> 15.99 | E10: =ITEM_MASTER_CLEAN!H10 -> 11 | F10: =ITEM_MASTER_CLEAN!I10 -> 4 | G10: =PAR_LEVELS!J10 -> 5.5714286 | H10: =PAR_LEVELS!K10 -> 1.8571429 | I10: =MAX(E10-G10,0) -> 5.4285714 | J10: =MAX(F10-H10,0) -> 2.1428571 | K10: =MAX(G10-E10,0) -> 0 | L10: =MAX(H10-F10,0) -> 0 | M10: =IF(AND(I10>TransferMin,L10>0),"OAK→HP",IF(AND(J10>TransferMin,K10>0),"HP→OAK","None")) -> None | N10: =IF(M10="OAK→HP",MIN(I10,L10),IF(M10="HP→OAK",MIN(J10,K10),0)) -> 0 | O10: =MAX(K10-IF(M10="HP→OAK",N10,0),0) -> 0 | P10: =MAX(L10-IF(M10="OAK→HP",N10,0),0) -> 0 | Q10: =IF(O10>0,CEILING(O10,ITEM_MASTER_CLEAN!G10),0) -> 0 | R10: =IF(P10>0,CEILING(P10,ITEM_MASTER_CLEAN!G10),0) -> 0 | S10: =IF(G10=0,0,(1-MIN(E10/MAX(G10,1),1))*50+(1-MIN(F10/MAX(H10,1),1))*50) -> 0
A11: =ITEM_MASTER_CLEAN!A11 -> 10 | B11: =ITEM_MASTER_CLEAN!B11 -> 25802 | C11: =ITEM_MASTER_CLEAN!C11 -> ACETATE ROLL 3.5"X1250" 4MM 1RL | D11: =ITEM_MASTER_CLEAN!F11 -> 23.42 | E11: =ITEM_MASTER_CLEAN!H11 -> 14 | F11: =ITEM_MASTER_CLEAN!I11 -> 11 | G11: =PAR_LEVELS!J11 -> 5.5714286 | H11: =PAR_LEVELS!K11 -> 5.5714286 | I11: =MAX(E11-G11,0) -> 8.4285714 | J11: =MAX(F11-H11,0) -> 5.4285714 | K11: =MAX(G11-E11,0) -> 0 | L11: =MAX(H11-F11,0) -> 0 | M11: =IF(AND(I11>TransferMin,L11>0),"OAK→HP",IF(AND(J11>TransferMin,K11>0),"HP→OAK","None")) -> None | N11: =IF(M11="OAK→HP",MIN(I11,L11),IF(M11="HP→OAK",MIN(J11,K11),0)) -> 0 | O11: =MAX(K11-IF(M11="HP→OAK",N11,0),0) -> 0 | P11: =MAX(L11-IF(M11="OAK→HP",N11,0),0) -> 0 | Q11: =IF(O11>0,CEILING(O11,ITEM_MASTER_CLEAN!G11),0) -> 0 | R11: =IF(P11>0,CEILING(P11,ITEM_MASTER_CLEAN!G11),0) -> 0 | S11: =IF(G11=0,0,(1-MIN(E11/MAX(G11,1),1))*50+(1-MIN(F11/MAX(H11,1),1))*50) -> 0
A12: =ITEM_MASTER_CLEAN!A12 -> 11 | B12: =ITEM_MASTER_CLEAN!B12 -> 19689 | C12: =ITEM_MASTER_CLEAN!C12 -> CAKE CUPCAKE BLACKOUT 8X4UN | D12: =ITEM_MASTER_CLEAN!F12 -> 13.82 | E12: =ITEM_MASTER_CLEAN!H12 -> 1 | F12: =ITEM_MASTER_CLEAN!I12 -> 1 | G12: =PAR_LEVELS!J12 -> 1.8571429 | H12: =PAR_LEVELS!K12 -> 1.8571429 | I12: =MAX(E12-G12,0) -> 0 | J12: =MAX(F12-H12,0) -> 0 | K12: =MAX(G12-E12,0) -> 0.85714286 | L12: =MAX(H12-F12,0) -> 0.85714286 | M12: =IF(AND(I12>TransferMin,L12>0),"OAK→HP",IF(AND(J12>TransferMin,K12>0),"HP→OAK","None")) -> None | N12: =IF(M12="OAK→HP",MIN(I12,L12),IF(M12="HP→OAK",MIN(J12,K12),0)) -> 0 | O12: =MAX(K12-IF(M12="HP→OAK",N12,0),0) -> 0.85714286 | P12: =MAX(L12-IF(M12="OAK→HP",N12,0),0) -> 0.85714286 | Q12: =IF(O12>0,CEILING(O12,ITEM_MASTER_CLEAN!G12),0) -> 8 | R12: =IF(P12>0,CEILING(P12,ITEM_MASTER_CLEAN!G12),0) -> 8 | S12: =IF(G12=0,0,(1-MIN(E12/MAX(G12,1),1))*50+(1-MIN(F12/MAX(H12,1),1))*50) -> 46.153846
A13: =ITEM_MASTER_CLEAN!A13 -> 12 | B13: =ITEM_MASTER_CLEAN!B13 -> 19692 | C13: =ITEM_MASTER_CLEAN!C13 -> CAKE CUPCAKE RED VELVET 8X4UN | D13: =ITEM_MASTER_CLEAN!F13 -> 21.36 | E13: =ITEM_MASTER_CLEAN!H13 -> 6 | F13: =ITEM_MASTER_CLEAN!I13 -> 4 | G13: =PAR_LEVELS!J13 -> 3.7142857 | H13: =PAR_LEVELS!K13 -> 1.8571429 | I13: =MAX(E13-G13,0) -> 2.2857143 | J13: =MAX(F13-H13,0) -> 2.1428571 | K13: =MAX(G13-E13,0) -> 0 | L13: =MAX(H13-F13,0) -> 0 | M13: =IF(AND(I13>TransferMin,L13>0),"OAK→HP",IF(AND(J13>TransferMin,K13>0),"HP→OAK","None")) -> None | N13: =IF(M13="OAK→HP",MIN(I13,L13),IF(M13="HP→OAK",MIN(J13,K13),0)) -> 0 | O13: =MAX(K13-IF(M13="HP→OAK",N13,0),0) -> 0 | P13: =MAX(L13-IF(M13="OAK→HP",N13,0),0) -> 0 | Q13: =IF(O13>0,CEILING(O13,ITEM_MASTER_CLEAN!G13),0) -> 0 | R13: =IF(P13>0,CEILING(P13,ITEM_MASTER_CLEAN!G13),0) -> 0 | S13: =IF(G13=0,0,(1-MIN(E13/MAX(G13,1),1))*50+(1-MIN(F13/MAX(H13,1),1))*50) -> 0
... A263: =ITEM_MASTER_CLEAN!A263 -> 262 | B263: =ITEM_MASTER_CLEAN!B263 -> 61804 | C263: =ITEM_MASTER_CLEAN!C263 -> LADIP BOX POPCORN 6X2.75X8.5 100 | D263: =ITEM_MASTER_CLEAN!F263 -> 16.46 | E263: =ITEM_MASTER_CLEAN!H263 -> 1 | F263: =ITEM_MASTER_CLEAN!I263 -> 1 | G263: =PAR_LEVELS!J263 -> 5.5714286 | H263: =PAR_LEVELS!K263 -> 1.8571429 | I263: =MAX(E263-G263,0) -> 0 | J263: =MAX(F263-H263,0) -> 0 | K263: =MAX(G263-E263,0) -> 4.5714286 | L263: =MAX(H263-F263,0) -> 0.85714286 | M263: =IF(AND(I263>TransferMin,L263>0),"OAK→HP",IF(AND(J263>TransferMin,K263>0),"HP→OAK","None")) -> None | N263: =IF(M263="OAK→HP",MIN(I263,L263),IF(M263="HP→OAK",MIN(J263,K263),0)) -> 0 | O263: =MAX(K263-IF(M263="HP→OAK",N263,0),0) -> 4.5714286 | P263: =MAX(L263-IF(M263="OAK→HP",N263,0),0) -> 0.85714286 | Q263: =IF(O263>0,CEILING(O263,ITEM_MASTER_CLEAN!G263),0) -> 5 | R263: =IF(P263>0,CEILING(P263,ITEM_MASTER_CLEAN!G263),0) -> 1 | S263: =IF(G263=0,0,(1-MIN(E263/MAX(G263,1),1))*50+(1-MIN(F263/MAX(H263,1),1))*50) -> 64.102564

Sheet LOW_CASH_MODE
